<?xml version="1.0" encoding="UTF-8"?>
<robot xmlns:controller="http://playerstage.sourceforge.net/gazebo/xmlschema/#controller"
	xmlns:interface="http://playerstage.sourceforge.net/gazebo/xmlschema/#interface"
	xmlns:sensor="http://playerstage.sourceforge.net/gazebo/xmlschema/#sensor"
	xmlns:xacro="http://ros.org/wiki/xacro">
	<xacro:macro name="x01"
		params="name parent minPosition maxPosition maxVelocity *origin">
		<link name="${name}_box_link">
			<visual>
				<geometry name="x01mesh">
					<mesh filename="package://herkulex_description/meshes/x01_box_plain.stl"
						scale="0.001 0.001 0.001" />
				</geometry>
				<material name="plastic_black">
					<color rgba="0.33 0.33 0.33 1" />
				</material>
				<origin rpy="-1.57075 1.57075 0" xyz="0 0 0.025" />
			</visual>
			<inertial>
				<mass value="0.01" />
				<inertia ixx="0.001" ixy="0.0" ixz="0.0" iyy="0.001" iyz="0.0"
					izz="0.001" />
			</inertial>
			<collision>
				<geometry name="x01simple">
					<box size="0.050 0.038 0.032" />
				</geometry>
			</collision>
		</link>
		<link name="${name}_link">
			<visual>
				<geometry>
					<cylinder length="0.005" radius="0.011" />
				</geometry>
				<material name="plastic_white">
					<color rgba="0.9 0.9 0.9 1" />
				</material>
				<origin rpy="0 1.57075 0" xyz="0.0025 0 0" />
			</visual>
			<inertial>
				<mass value="0.001" />
				<inertia ixx="0.001" ixy="0.0" ixz="0.0" iyy="0.001" iyz="0.0"
					izz="0.001" />
			</inertial>
		</link>
		<joint name="${name}_joint" type="revolute">
			<parent link="${name}_box_link" />
			<child link="${name}_link" />
			<origin xyz="0.0165 0 0.037" />
			<axis xyz="1 0 0" />
			<limit effort="0" lower="-1.5707" upper="1.5707" velocity="1" />
		</joint>
		<joint name="${name}_box_joint" type="fixed">
			<parent link="${parent}_link" />
			<child link="${name}_box_link" />
			<insert_block name="origin" />
		</joint>

		<!-- Gazebo Config -->
		<transmission name="${name}_trans">
			<type>transmission_interface/SimpleTransmission</type>
			<joint name="${name}_joint">
				<hardwareInterface>PositionJointInterface</hardwareInterface>
			</joint>
			<actuator name="${name}_motor">
				<hardwareInterface>PositionJointInterface</hardwareInterface>
				<mechanicalReduction>1</mechanicalReduction>
			</actuator>
		</transmission>

		<gazebo reference="${name}_box_link">
			<material>Gazebo/FlatBlack</material>
		</gazebo>
		<gazebo reference="${name}_link">
			<material>Gazebo/White</material>
		</gazebo>
	</xacro:macro>
	<xacro:macro name="x01inverted"
		params="name parent minPosition maxPosition maxVelocity *origin">
		<link name="${name}_box_link">
			<visual>
				<geometry name="x01mesh">
					<mesh filename="package://dynamixel_description/meshes/x01_box_plain.stl"
						scale="0.001 0.001 0.001" />
				</geometry>
				<material name="plastic_black" />
				<origin rpy="1.57075 0 3.14159" xyz="-0.012 0 0.019" />
			</visual>
			<inertial>
				<mass value="0.01" />
				<origin rpy="0 0 0" xyz="-0.012 0 0.019" />
				<inertia ixx="0.001" ixy="0.0" ixz="0.0" iyy="0.001" iyz="0.0"
					izz="0.001" />
			</inertial>
			<collision>
				<origin rpy="1.57075 0 3.14159" xyz="-0.012 0 0.019" />
				<geometry name="x01simple">
					<box size="0.050 0.038 0.032" />
				</geometry>
			</collision>
		</link>
		<link name="${name}_cyl_link">
			<visual>
				<geometry>
					<cylinder length="0.005" radius="0.011" />
				</geometry>
				<material name="plastic_white" />
				<origin rpy="0 0 0" xyz="0 0 0.0025" />
			</visual>
			<inertial>
				<mass value="0.001" />
				<inertia ixx="0.001" ixy="0.0" ixz="0.0" iyy="0.001" iyz="0.0"
					izz="0.001" />
				<origin rpy="0 0 0" xyz="0 0 0.0025" />
			</inertial>
			<collision>
				<geometry>
					<cylinder length="0.005" radius="0.011" />
					<origin rpy="0 0 0" xyz="0 0 0.0025" />
				</geometry>
			</collision>
		</link>
		<link name="${name}_link"></link>
		<joint name="${name}_joint" type="revolute">
			<parent link="${name}_cyl_link" />
			<child link="${name}_box_link" />
			<origin xyz="0 0 0" />
			<axis xyz="0 0 1" />
			<limit effort="0" lower="-1.5707" upper="1.5707" velocity="1" />
		</joint>
		<joint name="${name}_cyl_joint" type="fixed">
			<parent link="${parent}_link" />
			<child link="${name}_cyl_link" />
			<insert_block name="origin" />
		</joint>
		<joint name="${name}_box_joint" type="fixed">
			<parent link="${name}_box_link" />
			<child link="${name}_link" />
			<origin xyz="0 0 0.038" />
		</joint>

		<!-- Gazebo Config -->
		<transmission name="${name}_trans">
			<type>transmission_interface/SimpleTransmission</type>
			<joint name="${name}_joint">
				<hardwareInterface>PositionJointInterface</hardwareInterface>
			</joint>
			<actuator name="${name}_motor">
				<hardwareInterface>PositionJointInterface</hardwareInterface>
				<mechanicalReduction>1</mechanicalReduction>
			</actuator>
		</transmission>

		<gazebo reference="${name}_box_link">
			<material>Gazebo/FlatBlack</material>
		</gazebo>
		<gazebo reference="${name}_cyl_link">
			<material>Gazebo/White</material>
		</gazebo>
	</xacro:macro>
</robot>
