<?xml version="1.0" ?>
<!-- =================================================================================== -->
<!-- |    This document was autogenerated by xacro from kaspar.xacro                   | -->
<!-- |    EDITING THIS FILE BY HAND IS NOT RECOMMENDED                                 | -->
<!-- =================================================================================== -->
<robot name="kaspar" xmlns:controller="http://playerstage.sourceforge.net/gazebo/xmlschema/#controller" xmlns:interface="http://playerstage.sourceforge.net/gazebo/xmlschema/#interface" xmlns:sensor="http://playerstage.sourceforge.net/gazebo/xmlschema/#sensor" xmlns:xacro="http://www.ros.org/wiki/xacro">
  <!-- Constants -->
  <!-- Import joint description -->
  <!-- Import individual part macros -->
  <material name="trousers">
    <color rgba="0.0 0.0 0.8 1.0"/>
  </material>
  <material name="shell">
    <color rgba="1.0 1.0 1.0 0.25"/>
  </material>
  <material name="mount">
    <color rgba="0.2 0.2 0.2 0.75"/>
  </material>
  <material name="skin">
    <color rgba="1.0 0.850980392157 0.0588235294118 0.95"/>
  </material>
  <material name="plastic_green">
    <color rgba="0.1 0.8 0.3 1"/>
  </material>
  <material name="black">
    <color rgba="0.0 0.0 0.0 1.0"/>
  </material>
  <material name="blue">
    <color rgba="0.0 0.0 0.8 1.0"/>
  </material>
  <material name="green">
    <color rgba="0.0 0.8 0.0 1.0"/>
  </material>
  <material name="grey">
    <color rgba="0.2 0.2 0.2 1.0"/>
  </material>
  <material name="orange">
    <color rgba="1.0 0.423529411765 0.0392156862745 1.0"/>
  </material>
  <material name="brown">
    <color rgba="0.870588235294 0.811764705882 0.764705882353 1.0"/>
  </material>
  <material name="red">
    <color rgba="0.8 0.0 0.0 1.0"/>
  </material>
  <material name="white">
    <color rgba="1.0 1.0 1.0 1.0"/>
  </material>
  <!-- Used for fixing robot in the world -->
  <link name="world_link"/>
  <joint name="base_joint" type="fixed">
    <origin rpy="0 0 0" xyz="0 0 0"/>
    <parent link="world_link"/>
    <child link="base_link"/>
  </joint>
  <link name="base_link">
    <inertial>
      <origin rpy="0 0 0" xyz="0 0 0.05"/>
      <mass value="5"/>
      <inertia ixx="5.0" ixy="0.0" ixz="0.0" iyy="5.0" iyz="0.0" izz="5.0"/>
    </inertial>
    <visual>
      <origin rpy="0 0 0" xyz="0 0 0.05"/>
      <geometry>
        <cylinder length="0.10" radius="0.075"/>
      </geometry>
      <material name="trousers"/>
    </visual>
    <collision>
      <origin rpy="0 0 0" xyz="0 0 0.05"/>
      <geometry>
        <cylinder length="0.10" radius="0.075"/>
      </geometry>
    </collision>
  </link>
  <joint name="base_top_joint" type="fixed">
    <origin rpy="0 0 0" xyz="0 0 0.10"/>
    <parent link="base_link"/>
    <child link="base_top_link"/>
  </joint>
  <link name="base_top_link">
    <inertial>
      <origin rpy="0 0 0" xyz="0 0 0"/>
      <mass value="0.0001"/>
      <inertia ixx="0.001" ixy="0.0" ixz="0.0" iyy="0.001" iyz="0.0" izz="0.001"/>
    </inertial>
    <visual>
      <origin rpy="0 0 0" xyz="0 0 0"/>
      <geometry>
        <cylinder length="0.001" radius="0.01"/>
      </geometry>
      <material name="mount"/>
    </visual>
  </link>
  <gazebo reference="base_top_link">
    <material>Gazebo/Black</material>
  </gazebo>
  <joint name="base_leg_l_joint" type="fixed">
    <origin rpy="0 1.57079632679 0.785398163397" xyz="0.053033009 0.053033009 0.03"/>
    <parent link="base_link"/>
    <child link="base_leg_l_link"/>
  </joint>
  <link name="base_leg_l_link">
    <inertial>
      <origin rpy="0 0 0" xyz="0 0 0"/>
      <mass value="0.0001"/>
      <inertia ixx="0.001" ixy="0.0" ixz="0.0" iyy="0.001" iyz="0.0" izz="0.001"/>
    </inertial>
    <visual>
      <origin rpy="0 0 0" xyz="0 0 0"/>
      <geometry>
        <cylinder length="0.001" radius="0.01"/>
      </geometry>
      <material name="mount"/>
    </visual>
  </link>
  <gazebo reference="base_leg_l_link">
    <material>Gazebo/Black</material>
  </gazebo>
  <joint name="base_leg_r_joint" type="fixed">
    <origin rpy="0 1.57079632679 -0.785398163397" xyz="0.053033009 -0.053033009 0.03"/>
    <parent link="base_link"/>
    <child link="base_leg_r_link"/>
  </joint>
  <link name="base_leg_r_link">
    <inertial>
      <origin rpy="0 0 0" xyz="0 0 0"/>
      <mass value="0.0001"/>
      <inertia ixx="0.001" ixy="0.0" ixz="0.0" iyy="0.001" iyz="0.0" izz="0.001"/>
    </inertial>
    <visual>
      <origin rpy="0 0 0" xyz="0 0 0"/>
      <geometry>
        <cylinder length="0.001" radius="0.01"/>
      </geometry>
      <material name="mount"/>
    </visual>
  </link>
  <gazebo reference="base_leg_r_link">
    <material>Gazebo/Black</material>
  </gazebo>
  <gazebo reference="base_link">
    <material>Gazebo/Blue</material>
  </gazebo>
  <joint name="leg_l_mount_joint" type="fixed">
    <origin rpy="0 0 0" xyz="0 0 0"/>
    <parent link="base_leg_l_link"/>
    <child link="leg_l_mount_link"/>
  </joint>
  <link name="leg_l_mount_link">
    <inertial>
      <origin rpy="0 0 0" xyz="0 0 0"/>
      <mass value="0.0001"/>
      <inertia ixx="0.001" ixy="0.0" ixz="0.0" iyy="0.001" iyz="0.0" izz="0.001"/>
    </inertial>
    <visual>
      <origin rpy="0 0 0" xyz="0 0 0"/>
      <geometry>
        <cylinder length="0.001" radius="0.01"/>
      </geometry>
      <material name="mount"/>
    </visual>
  </link>
  <gazebo reference="leg_l_mount_link">
    <material>Gazebo/Black</material>
  </gazebo>
  <joint name="leg_l_joint" type="fixed">
    <origin rpy="0 0 0" xyz="0 0 0"/>
    <parent link="leg_l_mount_link"/>
    <child link="leg_l_link"/>
  </joint>
  <link name="leg_l_link">
    <inertial>
      <mass value="1"/>
      <inertia ixx="1.0" ixy="0.0" ixz="0.0" iyy="1.0" iyz="0.0" izz="1.0"/>
    </inertial>
    <visual>
      <origin rpy="0 0 0" xyz="0 0 0.05"/>
      <geometry>
        <cylinder length="0.10" radius="0.03"/>
      </geometry>
      <material name="trousers"/>
    </visual>
    <collision>
      <origin rpy="0 0 0" xyz="0 0 0.05"/>
      <geometry>
        <cylinder length="0.10" radius="0.03"/>
      </geometry>
    </collision>
  </link>
  <joint name="leg_l_foot_joint" type="fixed">
    <origin rpy="0 0 0" xyz="0 0 0.10"/>
    <parent link="leg_l_link"/>
    <child link="leg_l_foot_link"/>
  </joint>
  <link name="leg_l_foot_link">
    <inertial>
      <origin rpy="0 0 0" xyz="0 0 0"/>
      <mass value="0.0001"/>
      <inertia ixx="0.001" ixy="0.0" ixz="0.0" iyy="0.001" iyz="0.0" izz="0.001"/>
    </inertial>
    <visual>
      <origin rpy="0 0 0" xyz="0 0 0"/>
      <geometry>
        <cylinder length="0.001" radius="0.01"/>
      </geometry>
      <material name="mount"/>
    </visual>
  </link>
  <gazebo reference="leg_l_foot_link">
    <material>Gazebo/Black</material>
  </gazebo>
  <gazebo reference="leg_l_link">
    <material>Gazebo/Blue</material>
  </gazebo>
  <joint name="foot_l_mount_joint" type="fixed">
    <origin rpy="0 0 0" xyz="0 0 0"/>
    <parent link="leg_l_foot_link"/>
    <child link="foot_l_mount_link"/>
  </joint>
  <link name="foot_l_mount_link">
    <inertial>
      <origin rpy="0 0 0" xyz="0 0 0"/>
      <mass value="0.0001"/>
      <inertia ixx="0.001" ixy="0.0" ixz="0.0" iyy="0.001" iyz="0.0" izz="0.001"/>
    </inertial>
    <visual>
      <origin rpy="0 0 0" xyz="0 0 0"/>
      <geometry>
        <cylinder length="0.001" radius="0.01"/>
      </geometry>
      <material name="mount"/>
    </visual>
  </link>
  <gazebo reference="foot_l_mount_link">
    <material>Gazebo/Black</material>
  </gazebo>
  <joint name="foot_l_ankle_joint" type="fixed">
    <origin rpy="0 -1.57079632679 0" xyz="-0.0125 0 0.025"/>
    <parent link="foot_l_mount_link"/>
    <child link="foot_l_link"/>
  </joint>
  <link name="foot_l_link">
    <inertial>
      <mass value="0.5"/>
      <inertia ixx="0.5" ixy="0.0" ixz="0.0" iyy="0.5" iyz="0.0" izz="0.5"/>
    </inertial>
    <visual>
      <origin rpy="0 0 0" xyz="0 0 0"/>
      <geometry>
        <cylinder length="0.075" radius="0.025"/>
      </geometry>
      <material name="skin"/>
    </visual>
    <collision>
      <origin rpy="0 0 0" xyz="0 0 0"/>
      <geometry>
        <cylinder length="0.075" radius="0.025"/>
      </geometry>
    </collision>
  </link>
  <joint name="foot_l_toe_joint" type="fixed">
    <origin rpy="0 0 0" xyz="0 0 0.0375"/>
    <parent link="foot_l_link"/>
    <child link="foot_l_toe_link"/>
  </joint>
  <link name="foot_l_toe_link">
    <inertial>
      <origin rpy="0 0 0" xyz="0 0 0"/>
      <mass value="0.0001"/>
      <inertia ixx="0.001" ixy="0.0" ixz="0.0" iyy="0.001" iyz="0.0" izz="0.001"/>
    </inertial>
    <visual>
      <origin rpy="0 0 0" xyz="0 0 0"/>
      <geometry>
        <cylinder length="0.001" radius="0.01"/>
      </geometry>
      <material name="mount"/>
    </visual>
  </link>
  <gazebo reference="foot_l_toe_link">
    <material>Gazebo/Black</material>
  </gazebo>
  <gazebo reference="foot_l_link">
    <material>Gazebo/Yellow</material>
  </gazebo>
  <joint name="leg_r_mount_joint" type="fixed">
    <origin rpy="0 0 0" xyz="0 0 0"/>
    <parent link="base_leg_r_link"/>
    <child link="leg_r_mount_link"/>
  </joint>
  <link name="leg_r_mount_link">
    <inertial>
      <origin rpy="0 0 0" xyz="0 0 0"/>
      <mass value="0.0001"/>
      <inertia ixx="0.001" ixy="0.0" ixz="0.0" iyy="0.001" iyz="0.0" izz="0.001"/>
    </inertial>
    <visual>
      <origin rpy="0 0 0" xyz="0 0 0"/>
      <geometry>
        <cylinder length="0.001" radius="0.01"/>
      </geometry>
      <material name="mount"/>
    </visual>
  </link>
  <gazebo reference="leg_r_mount_link">
    <material>Gazebo/Black</material>
  </gazebo>
  <joint name="leg_r_joint" type="fixed">
    <origin rpy="0 0 0" xyz="0 0 0"/>
    <parent link="leg_r_mount_link"/>
    <child link="leg_r_link"/>
  </joint>
  <link name="leg_r_link">
    <inertial>
      <mass value="1"/>
      <inertia ixx="1.0" ixy="0.0" ixz="0.0" iyy="1.0" iyz="0.0" izz="1.0"/>
    </inertial>
    <visual>
      <origin rpy="0 0 0" xyz="0 0 0.05"/>
      <geometry>
        <cylinder length="0.10" radius="0.03"/>
      </geometry>
      <material name="trousers"/>
    </visual>
    <collision>
      <origin rpy="0 0 0" xyz="0 0 0.05"/>
      <geometry>
        <cylinder length="0.10" radius="0.03"/>
      </geometry>
    </collision>
  </link>
  <joint name="leg_r_foot_joint" type="fixed">
    <origin rpy="0 0 0" xyz="0 0 0.10"/>
    <parent link="leg_r_link"/>
    <child link="leg_r_foot_link"/>
  </joint>
  <link name="leg_r_foot_link">
    <inertial>
      <origin rpy="0 0 0" xyz="0 0 0"/>
      <mass value="0.0001"/>
      <inertia ixx="0.001" ixy="0.0" ixz="0.0" iyy="0.001" iyz="0.0" izz="0.001"/>
    </inertial>
    <visual>
      <origin rpy="0 0 0" xyz="0 0 0"/>
      <geometry>
        <cylinder length="0.001" radius="0.01"/>
      </geometry>
      <material name="mount"/>
    </visual>
  </link>
  <gazebo reference="leg_r_foot_link">
    <material>Gazebo/Black</material>
  </gazebo>
  <gazebo reference="leg_r_link">
    <material>Gazebo/Blue</material>
  </gazebo>
  <joint name="foot_r_mount_joint" type="fixed">
    <origin rpy="0 0 0" xyz="0 0 0"/>
    <parent link="leg_r_foot_link"/>
    <child link="foot_r_mount_link"/>
  </joint>
  <link name="foot_r_mount_link">
    <inertial>
      <origin rpy="0 0 0" xyz="0 0 0"/>
      <mass value="0.0001"/>
      <inertia ixx="0.001" ixy="0.0" ixz="0.0" iyy="0.001" iyz="0.0" izz="0.001"/>
    </inertial>
    <visual>
      <origin rpy="0 0 0" xyz="0 0 0"/>
      <geometry>
        <cylinder length="0.001" radius="0.01"/>
      </geometry>
      <material name="mount"/>
    </visual>
  </link>
  <gazebo reference="foot_r_mount_link">
    <material>Gazebo/Black</material>
  </gazebo>
  <joint name="foot_r_ankle_joint" type="fixed">
    <origin rpy="0 -1.57079632679 0" xyz="-0.0125 0 0.025"/>
    <parent link="foot_r_mount_link"/>
    <child link="foot_r_link"/>
  </joint>
  <link name="foot_r_link">
    <inertial>
      <mass value="0.5"/>
      <inertia ixx="0.5" ixy="0.0" ixz="0.0" iyy="0.5" iyz="0.0" izz="0.5"/>
    </inertial>
    <visual>
      <origin rpy="0 0 0" xyz="0 0 0"/>
      <geometry>
        <cylinder length="0.075" radius="0.025"/>
      </geometry>
      <material name="skin"/>
    </visual>
    <collision>
      <origin rpy="0 0 0" xyz="0 0 0"/>
      <geometry>
        <cylinder length="0.075" radius="0.025"/>
      </geometry>
    </collision>
  </link>
  <joint name="foot_r_toe_joint" type="fixed">
    <origin rpy="0 0 0" xyz="0 0 0.0375"/>
    <parent link="foot_r_link"/>
    <child link="foot_r_toe_link"/>
  </joint>
  <link name="foot_r_toe_link">
    <inertial>
      <origin rpy="0 0 0" xyz="0 0 0"/>
      <mass value="0.0001"/>
      <inertia ixx="0.001" ixy="0.0" ixz="0.0" iyy="0.001" iyz="0.0" izz="0.001"/>
    </inertial>
    <visual>
      <origin rpy="0 0 0" xyz="0 0 0"/>
      <geometry>
        <cylinder length="0.001" radius="0.01"/>
      </geometry>
      <material name="mount"/>
    </visual>
  </link>
  <gazebo reference="foot_r_toe_link">
    <material>Gazebo/Black</material>
  </gazebo>
  <gazebo reference="foot_r_link">
    <material>Gazebo/Yellow</material>
  </gazebo>
  <joint name="torso_mount_joint" type="fixed">
    <origin rpy="0 0 0" xyz="0 0 0"/>
    <parent link="base_top_link"/>
    <child link="torso_mount_link"/>
  </joint>
  <link name="torso_mount_link">
    <inertial>
      <origin rpy="0 0 0" xyz="0 0 0"/>
      <mass value="0.0001"/>
      <inertia ixx="0.001" ixy="0.0" ixz="0.0" iyy="0.001" iyz="0.0" izz="0.001"/>
    </inertial>
    <visual>
      <origin rpy="0 0 0" xyz="0 0 0"/>
      <geometry>
        <cylinder length="0.001" radius="0.01"/>
      </geometry>
      <material name="mount"/>
    </visual>
  </link>
  <gazebo reference="torso_mount_link">
    <material>Gazebo/Black</material>
  </gazebo>
  <joint name="torso_joint" type="revolute">
    <origin rpy="0 0 0" xyz="0 0 0"/>
    <parent link="torso_mount_link"/>
    <child link="torso_link"/>
    <axis xyz="0 0 1"/>
    <limit effort="0" lower="-1.5707" upper="1.5707" velocity="1"/>
    <dynamics damping="0.01" friction="0.01"/>
  </joint>
  <link name="torso_link">
    <inertial>
      <origin rpy="0 0 0" xyz="0 0 0.08"/>
      <mass value="0.001"/>
      <inertia ixx="0.01" ixy="0.0" ixz="0.0" iyy="0.01" iyz="0.0" izz="0.01"/>
    </inertial>
    <visual>
      <origin rpy="0 0 0" xyz="0 0 0.08"/>
      <geometry>
        <cylinder length="0.15" radius="0.08"/>
      </geometry>
      <material name="shell"/>
    </visual>
    <collision>
      <origin rpy="0 0 0" xyz="0 0 0.08"/>
      <geometry>
        <cylinder length="0.15" radius="0.08"/>
      </geometry>
    </collision>
  </link>
  <joint name="torso_top_joint" type="fixed">
    <origin rpy="0 0 0" xyz="0 0 0.155"/>
    <parent link="torso_link"/>
    <child link="torso_top_link"/>
  </joint>
  <link name="torso_top_link">
    <inertial>
      <origin rpy="0 0 0" xyz="0 0 0"/>
      <mass value="0.0001"/>
      <inertia ixx="0.001" ixy="0.0" ixz="0.0" iyy="0.001" iyz="0.0" izz="0.001"/>
    </inertial>
    <visual>
      <origin rpy="0 0 0" xyz="0 0 0"/>
      <geometry>
        <cylinder length="0.001" radius="0.01"/>
      </geometry>
      <material name="mount"/>
    </visual>
  </link>
  <gazebo reference="torso_top_link">
    <material>Gazebo/Black</material>
  </gazebo>
  <joint name="torso_arm_l_joint" type="fixed">
    <origin rpy="-1.57079632679 0 0" xyz="0 0.08 0.12"/>
    <parent link="torso_link"/>
    <child link="torso_arm_l_link"/>
  </joint>
  <link name="torso_arm_l_link">
    <inertial>
      <origin rpy="0 0 0" xyz="0 0 0"/>
      <mass value="0.0001"/>
      <inertia ixx="0.001" ixy="0.0" ixz="0.0" iyy="0.001" iyz="0.0" izz="0.001"/>
    </inertial>
    <visual>
      <origin rpy="0 0 0" xyz="0 0 0"/>
      <geometry>
        <cylinder length="0.001" radius="0.01"/>
      </geometry>
      <material name="mount"/>
    </visual>
  </link>
  <gazebo reference="torso_arm_l_link">
    <material>Gazebo/Black</material>
  </gazebo>
  <joint name="torso_arm_r_joint" type="fixed">
    <origin rpy="1.57079632679 0 0" xyz="0 -0.08 0.12"/>
    <parent link="torso_link"/>
    <child link="torso_arm_r_link"/>
  </joint>
  <link name="torso_arm_r_link">
    <inertial>
      <origin rpy="0 0 0" xyz="0 0 0"/>
      <mass value="0.0001"/>
      <inertia ixx="0.001" ixy="0.0" ixz="0.0" iyy="0.001" iyz="0.0" izz="0.001"/>
    </inertial>
    <visual>
      <origin rpy="0 0 0" xyz="0 0 0"/>
      <geometry>
        <cylinder length="0.001" radius="0.01"/>
      </geometry>
      <material name="mount"/>
    </visual>
  </link>
  <gazebo reference="torso_arm_r_link">
    <material>Gazebo/Black</material>
  </gazebo>
  <transmission name="torso_trans">
    <type>transmission_interface/SimpleTransmission</type>
    <joint name="torso_joint">
      <hardwareInterface>EffortJointInterface</hardwareInterface>
    </joint>
    <actuator name="torso_motor">
      <hardwareInterface>EffortJointInterface</hardwareInterface>
      <mechanicalReduction>1</mechanicalReduction>
    </actuator>
  </transmission>
  <gazebo reference="torso_link">
    <material>Gazebo/White</material>
  </gazebo>
  <joint name="arm_r_mount_joint" type="fixed">
    <origin rpy="0 0 0" xyz="0 0 0"/>
    <parent link="torso_arm_r_link"/>
    <child link="arm_r_mount_link"/>
  </joint>
  <link name="arm_r_mount_link">
    <inertial>
      <origin rpy="0 0 0" xyz="0 0 0"/>
      <mass value="0.0001"/>
      <inertia ixx="0.001" ixy="0.0" ixz="0.0" iyy="0.001" iyz="0.0" izz="0.001"/>
    </inertial>
    <visual>
      <origin rpy="0 0 0" xyz="0 0 0"/>
      <geometry>
        <cylinder length="0.001" radius="0.01"/>
      </geometry>
      <material name="mount"/>
    </visual>
  </link>
  <gazebo reference="arm_r_mount_link">
    <material>Gazebo/Black</material>
  </gazebo>
  <joint name="arm_r_0_mount_joint" type="fixed">
    <origin xyz="0 0 0"/>
    <parent link="arm_r_mount_link"/>
    <child link="arm_r_0_mount_link"/>
  </joint>
  <link name="arm_r_0_mount_link">
    <inertial>
      <origin rpy="0 0 0" xyz="0 0 0"/>
      <mass value="0.0001"/>
      <inertia ixx="0.001" ixy="0.0" ixz="0.0" iyy="0.001" iyz="0.0" izz="0.001"/>
    </inertial>
    <visual>
      <origin rpy="0 0 0" xyz="0 0 0"/>
      <geometry>
        <cylinder length="0.001" radius="0.01"/>
      </geometry>
      <material name="mount"/>
    </visual>
  </link>
  <gazebo reference="arm_r_0_mount_link">
    <material>Gazebo/Black</material>
  </gazebo>
  <link name="arm_r_0_box_link">
    <visual>
      <geometry name="x01mesh">
        <mesh filename="package://herkulex_description/meshes/x01_box_plain.stl" scale="0.001 0.001 0.001"/>
      </geometry>
      <material name="plastic_black"/>
      <origin rpy="3.14159265359 0 0" xyz="0 0 0"/>
    </visual>
    <inertial>
      <mass value="0.001"/>
      <inertia ixx="0.01" ixy="0.0" ixz="0.0" iyy="0.01" iyz="0.0" izz="0.01"/>
    </inertial>
    <collision>
      <geometry name="x01">
        <box size="0.050 0.038 0.032"/>
      </geometry>
    </collision>
  </link>
  <joint name="arm_r_0_box_bottom_joint" type="fixed">
    <origin rpy="0 1.57079632679 0" xyz="0.025 0 0"/>
    <parent link="arm_r_0_box_link"/>
    <child link="arm_r_0_box_bottom_link"/>
  </joint>
  <link name="arm_r_0_box_bottom_link">
    <inertial>
      <origin rpy="0 0 0" xyz="0 0 0"/>
      <mass value="0.0001"/>
      <inertia ixx="0.001" ixy="0.0" ixz="0.0" iyy="0.001" iyz="0.0" izz="0.001"/>
    </inertial>
    <visual>
      <origin rpy="0 0 0" xyz="0 0 0"/>
      <geometry>
        <cylinder length="0.001" radius="0.01"/>
      </geometry>
      <material name="mount"/>
    </visual>
  </link>
  <gazebo reference="arm_r_0_box_bottom_link">
    <material>Gazebo/Black</material>
  </gazebo>
  <joint name="arm_r_0_box_axel_joint" type="fixed">
    <origin rpy="1.57079632679 0 3.14159265359" xyz="-0.012 0.019 0"/>
    <parent link="arm_r_0_box_link"/>
    <child link="arm_r_0_box_axel_link"/>
  </joint>
  <link name="arm_r_0_box_axel_link">
    <inertial>
      <origin rpy="0 0 0" xyz="0 0 0"/>
      <mass value="0.0001"/>
      <inertia ixx="0.001" ixy="0.0" ixz="0.0" iyy="0.001" iyz="0.0" izz="0.001"/>
    </inertial>
    <visual>
      <origin rpy="0 0 0" xyz="0 0 0"/>
      <geometry>
        <cylinder length="0.001" radius="0.01"/>
      </geometry>
      <material name="mount"/>
    </visual>
  </link>
  <gazebo reference="arm_r_0_box_axel_link">
    <material>Gazebo/Black</material>
  </gazebo>
  <joint name="arm_r_0_box_joint" type="fixed">
    <origin rpy="1.57079632679 0 -1.57079632679" xyz="0 0 0.019"/>
    <parent link="arm_r_0_mount_link"/>
    <child link="arm_r_0_box_link"/>
  </joint>
  <link name="arm_r_0_axel_box_link">
    <visual>
      <geometry>
        <cylinder length="0.005" radius="0.011"/>
      </geometry>
      <material name="plastic_white"/>
    </visual>
    <inertial>
      <mass value="0.001"/>
      <inertia ixx="0.001" ixy="0.0" ixz="0.0" iyy="0.001" iyz="0.0" izz="0.001"/>
    </inertial>
    <collision>
      <geometry>
        <cylinder length="0.005" radius="0.011"/>
      </geometry>
    </collision>
  </link>
  <joint name="arm_r_0_axel_joint" type="fixed">
    <origin rpy="0 0 1.57079632679" xyz="0 0 0.0025"/>
    <parent link="arm_r_0_axel_box_link"/>
    <child link="arm_r_0_axel_link"/>
  </joint>
  <link name="arm_r_0_axel_link">
    <inertial>
      <origin rpy="0 0 0" xyz="0 0 0"/>
      <mass value="0.0001"/>
      <inertia ixx="0.001" ixy="0.0" ixz="0.0" iyy="0.001" iyz="0.0" izz="0.001"/>
    </inertial>
    <visual>
      <origin rpy="0 0 0" xyz="0 0 0"/>
      <geometry>
        <cylinder length="0.001" radius="0.01"/>
      </geometry>
      <material name="mount"/>
    </visual>
  </link>
  <gazebo reference="arm_r_0_axel_link">
    <material>Gazebo/Black</material>
  </gazebo>
  <joint name="arm_r_0_joint" type="revolute">
    <parent link="arm_r_0_box_axel_link"/>
    <child link="arm_r_0_axel_box_link"/>
    <origin rpy="0 0 0" xyz="0 0 0"/>
    <axis xyz="0 0 1"/>
    <limit effort="100" lower="3.14159265359" upper="3.14159265359" velocity="1"/>
    <dynamics damping="0.01" friction="0.01"/>
  </joint>
  <transmission name="arm_r_0_trans">
    <type>transmission_interface/SimpleTransmission</type>
    <joint name="arm_r_0_joint">
      <hardwareInterface>EffortJointInterface</hardwareInterface>
    </joint>
    <actuator name="arm_r_0_motor">
      <hardwareInterface>EffortJointInterface</hardwareInterface>
      <mechanicalReduction>1</mechanicalReduction>
    </actuator>
  </transmission>
  <gazebo reference="arm_r_0_box_link">
    <material>Gazebo/White</material>
  </gazebo>
  <gazebo reference="arm_r_0_box_axel_link">
    <material>Gazebo/White</material>
  </gazebo>
  <joint name="arm_r_1_mount_joint" type="fixed">
    <origin xyz="0 0 0"/>
    <parent link="arm_r_0_axel_link"/>
    <child link="arm_r_1_mount_link"/>
  </joint>
  <link name="arm_r_1_mount_link">
    <inertial>
      <origin rpy="0 0 0" xyz="0 0 0"/>
      <mass value="0.0001"/>
      <inertia ixx="0.001" ixy="0.0" ixz="0.0" iyy="0.001" iyz="0.0" izz="0.001"/>
    </inertial>
    <visual>
      <origin rpy="0 0 0" xyz="0 0 0"/>
      <geometry>
        <cylinder length="0.001" radius="0.01"/>
      </geometry>
      <material name="mount"/>
    </visual>
  </link>
  <gazebo reference="arm_r_1_mount_link">
    <material>Gazebo/Black</material>
  </gazebo>
  <link name="arm_r_1_box_link">
    <visual>
      <geometry name="x01mesh">
        <mesh filename="package://herkulex_description/meshes/x01_box_plain.stl" scale="0.001 0.001 0.001"/>
      </geometry>
      <material name="plastic_black"/>
      <origin rpy="3.14159265359 0 0" xyz="0 0 0"/>
    </visual>
    <inertial>
      <mass value="0.001"/>
      <inertia ixx="0.01" ixy="0.0" ixz="0.0" iyy="0.01" iyz="0.0" izz="0.01"/>
    </inertial>
    <collision>
      <geometry name="x01">
        <box size="0.050 0.038 0.032"/>
      </geometry>
    </collision>
  </link>
  <joint name="arm_r_1_box_back_joint" type="fixed">
    <origin rpy="1.57079632679 0 0" xyz="0 -0.019 0"/>
    <parent link="arm_r_1_box_link"/>
    <child link="arm_r_1_box_back_link"/>
  </joint>
  <link name="arm_r_1_box_back_link">
    <inertial>
      <origin rpy="0 0 0" xyz="0 0 0"/>
      <mass value="0.0001"/>
      <inertia ixx="0.001" ixy="0.0" ixz="0.0" iyy="0.001" iyz="0.0" izz="0.001"/>
    </inertial>
    <visual>
      <origin rpy="0 0 0" xyz="0 0 0"/>
      <geometry>
        <cylinder length="0.001" radius="0.01"/>
      </geometry>
      <material name="mount"/>
    </visual>
  </link>
  <gazebo reference="arm_r_1_box_back_link">
    <material>Gazebo/Black</material>
  </gazebo>
  <joint name="arm_r_1_box_axel_joint" type="fixed">
    <origin rpy="1.57079632679 0 3.14159265359" xyz="-0.012 0.019 0"/>
    <parent link="arm_r_1_box_link"/>
    <child link="arm_r_1_box_axel_link"/>
  </joint>
  <link name="arm_r_1_box_axel_link">
    <inertial>
      <origin rpy="0 0 0" xyz="0 0 0"/>
      <mass value="0.0001"/>
      <inertia ixx="0.001" ixy="0.0" ixz="0.0" iyy="0.001" iyz="0.0" izz="0.001"/>
    </inertial>
    <visual>
      <origin rpy="0 0 0" xyz="0 0 0"/>
      <geometry>
        <cylinder length="0.001" radius="0.01"/>
      </geometry>
      <material name="mount"/>
    </visual>
  </link>
  <gazebo reference="arm_r_1_box_axel_link">
    <material>Gazebo/Black</material>
  </gazebo>
  <joint name="arm_r_1_box_joint" type="fixed">
    <origin rpy="0 1.57079632679 0" xyz="0 0 0.025"/>
    <parent link="arm_r_1_mount_link"/>
    <child link="arm_r_1_box_link"/>
  </joint>
  <link name="arm_r_1_axel_box_link">
    <visual>
      <geometry>
        <cylinder length="0.005" radius="0.011"/>
      </geometry>
      <material name="plastic_white"/>
    </visual>
    <inertial>
      <mass value="0.001"/>
      <inertia ixx="0.001" ixy="0.0" ixz="0.0" iyy="0.001" iyz="0.0" izz="0.001"/>
    </inertial>
    <collision>
      <geometry>
        <cylinder length="0.005" radius="0.011"/>
      </geometry>
    </collision>
  </link>
  <joint name="arm_r_1_axel_joint" type="fixed">
    <origin rpy="0 0 1.57079632679" xyz="0 0 0.0025"/>
    <parent link="arm_r_1_axel_box_link"/>
    <child link="arm_r_1_axel_link"/>
  </joint>
  <link name="arm_r_1_axel_link">
    <inertial>
      <origin rpy="0 0 0" xyz="0 0 0"/>
      <mass value="0.0001"/>
      <inertia ixx="0.001" ixy="0.0" ixz="0.0" iyy="0.001" iyz="0.0" izz="0.001"/>
    </inertial>
    <visual>
      <origin rpy="0 0 0" xyz="0 0 0"/>
      <geometry>
        <cylinder length="0.001" radius="0.01"/>
      </geometry>
      <material name="mount"/>
    </visual>
  </link>
  <gazebo reference="arm_r_1_axel_link">
    <material>Gazebo/Black</material>
  </gazebo>
  <joint name="arm_r_1_joint" type="revolute">
    <parent link="arm_r_1_box_axel_link"/>
    <child link="arm_r_1_axel_box_link"/>
    <origin rpy="0 0 0" xyz="0 0 0"/>
    <axis xyz="0 0 1"/>
    <limit effort="100" lower="3.14159265359" upper="3.14159265359" velocity="1"/>
    <dynamics damping="0.01" friction="0.01"/>
  </joint>
  <transmission name="arm_r_1_trans">
    <type>transmission_interface/SimpleTransmission</type>
    <joint name="arm_r_1_joint">
      <hardwareInterface>EffortJointInterface</hardwareInterface>
    </joint>
    <actuator name="arm_r_1_motor">
      <hardwareInterface>EffortJointInterface</hardwareInterface>
      <mechanicalReduction>1</mechanicalReduction>
    </actuator>
  </transmission>
  <gazebo reference="arm_r_1_box_link">
    <material>Gazebo/White</material>
  </gazebo>
  <gazebo reference="arm_r_1_box_axel_link">
    <material>Gazebo/White</material>
  </gazebo>
  <joint name="arm_r_2_mount_joint" type="fixed">
    <origin xyz="0 0 0"/>
    <parent link="arm_r_1_axel_link"/>
    <child link="arm_r_2_mount_link"/>
  </joint>
  <link name="arm_r_2_mount_link">
    <inertial>
      <origin rpy="0 0 0" xyz="0 0 0"/>
      <mass value="0.0001"/>
      <inertia ixx="0.001" ixy="0.0" ixz="0.0" iyy="0.001" iyz="0.0" izz="0.001"/>
    </inertial>
    <visual>
      <origin rpy="0 0 0" xyz="0 0 0"/>
      <geometry>
        <cylinder length="0.001" radius="0.01"/>
      </geometry>
      <material name="mount"/>
    </visual>
  </link>
  <gazebo reference="arm_r_2_mount_link">
    <material>Gazebo/Black</material>
  </gazebo>
  <link name="arm_r_2_box_link">
    <visual>
      <geometry name="x01mesh">
        <mesh filename="package://herkulex_description/meshes/x01_box_plain.stl" scale="0.001 0.001 0.001"/>
      </geometry>
      <material name="plastic_black"/>
      <origin rpy="3.14159265359 0 0" xyz="0 0 0"/>
    </visual>
    <inertial>
      <mass value="0.001"/>
      <inertia ixx="0.01" ixy="0.0" ixz="0.0" iyy="0.01" iyz="0.0" izz="0.01"/>
    </inertial>
    <collision>
      <geometry name="x01">
        <box size="0.050 0.038 0.032"/>
      </geometry>
    </collision>
  </link>
  <joint name="arm_r_2_box_back_joint" type="fixed">
    <origin rpy="1.57079632679 0 0" xyz="0 -0.019 0"/>
    <parent link="arm_r_2_box_link"/>
    <child link="arm_r_2_box_back_link"/>
  </joint>
  <link name="arm_r_2_box_back_link">
    <inertial>
      <origin rpy="0 0 0" xyz="0 0 0"/>
      <mass value="0.0001"/>
      <inertia ixx="0.001" ixy="0.0" ixz="0.0" iyy="0.001" iyz="0.0" izz="0.001"/>
    </inertial>
    <visual>
      <origin rpy="0 0 0" xyz="0 0 0"/>
      <geometry>
        <cylinder length="0.001" radius="0.01"/>
      </geometry>
      <material name="mount"/>
    </visual>
  </link>
  <gazebo reference="arm_r_2_box_back_link">
    <material>Gazebo/Black</material>
  </gazebo>
  <joint name="arm_r_2_box_axel_joint" type="fixed">
    <origin rpy="1.57079632679 0 3.14159265359" xyz="-0.012 0.019 0"/>
    <parent link="arm_r_2_box_link"/>
    <child link="arm_r_2_box_axel_link"/>
  </joint>
  <link name="arm_r_2_box_axel_link">
    <inertial>
      <origin rpy="0 0 0" xyz="0 0 0"/>
      <mass value="0.0001"/>
      <inertia ixx="0.001" ixy="0.0" ixz="0.0" iyy="0.001" iyz="0.0" izz="0.001"/>
    </inertial>
    <visual>
      <origin rpy="0 0 0" xyz="0 0 0"/>
      <geometry>
        <cylinder length="0.001" radius="0.01"/>
      </geometry>
      <material name="mount"/>
    </visual>
  </link>
  <gazebo reference="arm_r_2_box_axel_link">
    <material>Gazebo/Black</material>
  </gazebo>
  <joint name="arm_r_2_box_joint" type="fixed">
    <origin rpy="0 1.57079632679 0" xyz="0 0 0.025"/>
    <parent link="arm_r_2_mount_link"/>
    <child link="arm_r_2_box_link"/>
  </joint>
  <link name="arm_r_2_axel_box_link">
    <visual>
      <geometry>
        <cylinder length="0.005" radius="0.011"/>
      </geometry>
      <material name="plastic_white"/>
    </visual>
    <inertial>
      <mass value="0.001"/>
      <inertia ixx="0.001" ixy="0.0" ixz="0.0" iyy="0.001" iyz="0.0" izz="0.001"/>
    </inertial>
    <collision>
      <geometry>
        <cylinder length="0.005" radius="0.011"/>
      </geometry>
    </collision>
  </link>
  <joint name="arm_r_2_axel_joint" type="fixed">
    <origin rpy="0 0 1.57079632679" xyz="0 0 0.0025"/>
    <parent link="arm_r_2_axel_box_link"/>
    <child link="arm_r_2_axel_link"/>
  </joint>
  <link name="arm_r_2_axel_link">
    <inertial>
      <origin rpy="0 0 0" xyz="0 0 0"/>
      <mass value="0.0001"/>
      <inertia ixx="0.001" ixy="0.0" ixz="0.0" iyy="0.001" iyz="0.0" izz="0.001"/>
    </inertial>
    <visual>
      <origin rpy="0 0 0" xyz="0 0 0"/>
      <geometry>
        <cylinder length="0.001" radius="0.01"/>
      </geometry>
      <material name="mount"/>
    </visual>
  </link>
  <gazebo reference="arm_r_2_axel_link">
    <material>Gazebo/Black</material>
  </gazebo>
  <joint name="arm_r_2_joint" type="revolute">
    <parent link="arm_r_2_box_axel_link"/>
    <child link="arm_r_2_axel_box_link"/>
    <origin rpy="0 0 0" xyz="0 0 0"/>
    <axis xyz="0 0 1"/>
    <limit effort="100" lower="3.14159265359" upper="3.14159265359" velocity="1"/>
    <dynamics damping="0.01" friction="0.01"/>
  </joint>
  <transmission name="arm_r_2_trans">
    <type>transmission_interface/SimpleTransmission</type>
    <joint name="arm_r_2_joint">
      <hardwareInterface>EffortJointInterface</hardwareInterface>
    </joint>
    <actuator name="arm_r_2_motor">
      <hardwareInterface>EffortJointInterface</hardwareInterface>
      <mechanicalReduction>1</mechanicalReduction>
    </actuator>
  </transmission>
  <gazebo reference="arm_r_2_box_link">
    <material>Gazebo/White</material>
  </gazebo>
  <gazebo reference="arm_r_2_box_axel_link">
    <material>Gazebo/White</material>
  </gazebo>
  <joint name="arm_r_3_mount_joint" type="fixed">
    <origin xyz="0 0 0"/>
    <parent link="arm_r_2_axel_link"/>
    <child link="arm_r_3_mount_link"/>
  </joint>
  <link name="arm_r_3_mount_link">
    <inertial>
      <origin rpy="0 0 0" xyz="0 0 0"/>
      <mass value="0.0001"/>
      <inertia ixx="0.001" ixy="0.0" ixz="0.0" iyy="0.001" iyz="0.0" izz="0.001"/>
    </inertial>
    <visual>
      <origin rpy="0 0 0" xyz="0 0 0"/>
      <geometry>
        <cylinder length="0.001" radius="0.01"/>
      </geometry>
      <material name="mount"/>
    </visual>
  </link>
  <gazebo reference="arm_r_3_mount_link">
    <material>Gazebo/Black</material>
  </gazebo>
  <link name="arm_r_3_box_link">
    <visual>
      <geometry name="x01mesh">
        <mesh filename="package://herkulex_description/meshes/x01_box_plain.stl" scale="0.001 0.001 0.001"/>
      </geometry>
      <material name="plastic_black"/>
      <origin rpy="3.14159265359 0 0" xyz="0 0 0"/>
    </visual>
    <inertial>
      <mass value="0.001"/>
      <inertia ixx="0.01" ixy="0.0" ixz="0.0" iyy="0.01" iyz="0.0" izz="0.01"/>
    </inertial>
    <collision>
      <geometry name="x01">
        <box size="0.050 0.038 0.032"/>
      </geometry>
    </collision>
  </link>
  <joint name="arm_r_3_box_back_joint" type="fixed">
    <origin rpy="1.57079632679 0 0" xyz="0 -0.019 0"/>
    <parent link="arm_r_3_box_link"/>
    <child link="arm_r_3_box_back_link"/>
  </joint>
  <link name="arm_r_3_box_back_link">
    <inertial>
      <origin rpy="0 0 0" xyz="0 0 0"/>
      <mass value="0.0001"/>
      <inertia ixx="0.001" ixy="0.0" ixz="0.0" iyy="0.001" iyz="0.0" izz="0.001"/>
    </inertial>
    <visual>
      <origin rpy="0 0 0" xyz="0 0 0"/>
      <geometry>
        <cylinder length="0.001" radius="0.01"/>
      </geometry>
      <material name="mount"/>
    </visual>
  </link>
  <gazebo reference="arm_r_3_box_back_link">
    <material>Gazebo/Black</material>
  </gazebo>
  <joint name="arm_r_3_box_axel_joint" type="fixed">
    <origin rpy="1.57079632679 0 3.14159265359" xyz="-0.012 0.019 0"/>
    <parent link="arm_r_3_box_link"/>
    <child link="arm_r_3_box_axel_link"/>
  </joint>
  <link name="arm_r_3_box_axel_link">
    <inertial>
      <origin rpy="0 0 0" xyz="0 0 0"/>
      <mass value="0.0001"/>
      <inertia ixx="0.001" ixy="0.0" ixz="0.0" iyy="0.001" iyz="0.0" izz="0.001"/>
    </inertial>
    <visual>
      <origin rpy="0 0 0" xyz="0 0 0"/>
      <geometry>
        <cylinder length="0.001" radius="0.01"/>
      </geometry>
      <material name="mount"/>
    </visual>
  </link>
  <gazebo reference="arm_r_3_box_axel_link">
    <material>Gazebo/Black</material>
  </gazebo>
  <joint name="arm_r_3_box_joint" type="fixed">
    <origin rpy="0 1.57079632679 0" xyz="0 0 0.025"/>
    <parent link="arm_r_3_mount_link"/>
    <child link="arm_r_3_box_link"/>
  </joint>
  <link name="arm_r_3_axel_box_link">
    <visual>
      <geometry>
        <cylinder length="0.005" radius="0.011"/>
      </geometry>
      <material name="plastic_white"/>
    </visual>
    <inertial>
      <mass value="0.001"/>
      <inertia ixx="0.001" ixy="0.0" ixz="0.0" iyy="0.001" iyz="0.0" izz="0.001"/>
    </inertial>
    <collision>
      <geometry>
        <cylinder length="0.005" radius="0.011"/>
      </geometry>
    </collision>
  </link>
  <joint name="arm_r_3_axel_joint" type="fixed">
    <origin rpy="0 0 1.57079632679" xyz="0 0 0.0025"/>
    <parent link="arm_r_3_axel_box_link"/>
    <child link="arm_r_3_axel_link"/>
  </joint>
  <link name="arm_r_3_axel_link">
    <inertial>
      <origin rpy="0 0 0" xyz="0 0 0"/>
      <mass value="0.0001"/>
      <inertia ixx="0.001" ixy="0.0" ixz="0.0" iyy="0.001" iyz="0.0" izz="0.001"/>
    </inertial>
    <visual>
      <origin rpy="0 0 0" xyz="0 0 0"/>
      <geometry>
        <cylinder length="0.001" radius="0.01"/>
      </geometry>
      <material name="mount"/>
    </visual>
  </link>
  <gazebo reference="arm_r_3_axel_link">
    <material>Gazebo/Black</material>
  </gazebo>
  <joint name="arm_r_3_joint" type="revolute">
    <parent link="arm_r_3_box_axel_link"/>
    <child link="arm_r_3_axel_box_link"/>
    <origin rpy="0 0 0" xyz="0 0 0"/>
    <axis xyz="0 0 1"/>
    <limit effort="100" lower="3.14159265359" upper="3.14159265359" velocity="1"/>
    <dynamics damping="0.01" friction="0.01"/>
  </joint>
  <transmission name="arm_r_3_trans">
    <type>transmission_interface/SimpleTransmission</type>
    <joint name="arm_r_3_joint">
      <hardwareInterface>EffortJointInterface</hardwareInterface>
    </joint>
    <actuator name="arm_r_3_motor">
      <hardwareInterface>EffortJointInterface</hardwareInterface>
      <mechanicalReduction>1</mechanicalReduction>
    </actuator>
  </transmission>
  <gazebo reference="arm_r_3_box_link">
    <material>Gazebo/White</material>
  </gazebo>
  <gazebo reference="arm_r_3_box_axel_link">
    <material>Gazebo/White</material>
  </gazebo>
  <joint name="arm_r_hand_joint" type="fixed">
    <origin rpy="0 0 0" xyz="0 0 0"/>
    <parent link="arm_r_3_axel_link"/>
    <child link="arm_r_hand_link"/>
  </joint>
  <link name="arm_r_hand_link">
    <inertial>
      <origin rpy="0 0 0" xyz="0 0 0"/>
      <mass value="0.0001"/>
      <inertia ixx="0.001" ixy="0.0" ixz="0.0" iyy="0.001" iyz="0.0" izz="0.001"/>
    </inertial>
    <visual>
      <origin rpy="0 0 0" xyz="0 0 0"/>
      <geometry>
        <cylinder length="0.001" radius="0.01"/>
      </geometry>
      <material name="mount"/>
    </visual>
  </link>
  <gazebo reference="arm_r_hand_link">
    <material>Gazebo/Black</material>
  </gazebo>
  <joint name="hand_r_mount_joint" type="fixed">
    <origin rpy="0 0 0" xyz="0 0 0"/>
    <parent link="arm_r_hand_link"/>
    <child link="hand_r_mount_link"/>
  </joint>
  <link name="hand_r_mount_link">
    <inertial>
      <origin rpy="0 0 0" xyz="0 0 0"/>
      <mass value="0.0001"/>
      <inertia ixx="0.001" ixy="0.0" ixz="0.0" iyy="0.001" iyz="0.0" izz="0.001"/>
    </inertial>
    <visual>
      <origin rpy="0 0 0" xyz="0 0 0"/>
      <geometry>
        <cylinder length="0.001" radius="0.01"/>
      </geometry>
      <material name="mount"/>
    </visual>
  </link>
  <gazebo reference="hand_r_mount_link">
    <material>Gazebo/Black</material>
  </gazebo>
  <joint name="hand_r_wrist_joint" type="fixed">
    <origin rpy="0 0 0" xyz="0 0 0.0275"/>
    <parent link="hand_r_mount_link"/>
    <child link="hand_r_link"/>
  </joint>
  <link name="hand_r_link">
    <inertial>
      <mass value="0.25"/>
      <inertia ixx="0.25" ixy="0.0" ixz="0.0" iyy="0.25" iyz="0.0" izz="0.25"/>
    </inertial>
    <visual>
      <origin rpy="0 0 0" xyz="0 0 0"/>
      <geometry>
        <cylinder length="0.055" radius="0.015"/>
      </geometry>
      <material name="skin"/>
    </visual>
    <collision>
      <origin rpy="0 0 0" xyz="0 0 0"/>
      <geometry>
        <cylinder length="0.055" radius="0.015"/>
      </geometry>
    </collision>
  </link>
  <joint name="hand_r_fingers_joint" type="fixed">
    <origin rpy="0 0 0" xyz="0 0 0.0275"/>
    <parent link="hand_r_link"/>
    <child link="hand_r_fingers_link"/>
  </joint>
  <link name="hand_r_fingers_link">
    <inertial>
      <origin rpy="0 0 0" xyz="0 0 0"/>
      <mass value="0.0001"/>
      <inertia ixx="0.001" ixy="0.0" ixz="0.0" iyy="0.001" iyz="0.0" izz="0.001"/>
    </inertial>
    <visual>
      <origin rpy="0 0 0" xyz="0 0 0"/>
      <geometry>
        <cylinder length="0.001" radius="0.01"/>
      </geometry>
      <material name="mount"/>
    </visual>
  </link>
  <gazebo reference="hand_r_fingers_link">
    <material>Gazebo/Black</material>
  </gazebo>
  <gazebo reference="hand_r_link">
    <material>Gazebo/Yellow</material>
  </gazebo>
  <joint name="arm_l_mount_joint" type="fixed">
    <origin rpy="0 0 3.14159265359" xyz="0 0 0"/>
    <parent link="torso_arm_l_link"/>
    <child link="arm_l_mount_link"/>
  </joint>
  <link name="arm_l_mount_link">
    <inertial>
      <origin rpy="0 0 0" xyz="0 0 0"/>
      <mass value="0.0001"/>
      <inertia ixx="0.001" ixy="0.0" ixz="0.0" iyy="0.001" iyz="0.0" izz="0.001"/>
    </inertial>
    <visual>
      <origin rpy="0 0 0" xyz="0 0 0"/>
      <geometry>
        <cylinder length="0.001" radius="0.01"/>
      </geometry>
      <material name="mount"/>
    </visual>
  </link>
  <gazebo reference="arm_l_mount_link">
    <material>Gazebo/Black</material>
  </gazebo>
  <joint name="arm_l_0_mount_joint" type="fixed">
    <origin xyz="0 0 0"/>
    <parent link="arm_l_mount_link"/>
    <child link="arm_l_0_mount_link"/>
  </joint>
  <link name="arm_l_0_mount_link">
    <inertial>
      <origin rpy="0 0 0" xyz="0 0 0"/>
      <mass value="0.0001"/>
      <inertia ixx="0.001" ixy="0.0" ixz="0.0" iyy="0.001" iyz="0.0" izz="0.001"/>
    </inertial>
    <visual>
      <origin rpy="0 0 0" xyz="0 0 0"/>
      <geometry>
        <cylinder length="0.001" radius="0.01"/>
      </geometry>
      <material name="mount"/>
    </visual>
  </link>
  <gazebo reference="arm_l_0_mount_link">
    <material>Gazebo/Black</material>
  </gazebo>
  <link name="arm_l_0_box_link">
    <visual>
      <geometry name="x01mesh">
        <mesh filename="package://herkulex_description/meshes/x01_box_plain.stl" scale="0.001 0.001 0.001"/>
      </geometry>
      <material name="plastic_black"/>
      <origin rpy="3.14159265359 0 0" xyz="0 0 0"/>
    </visual>
    <inertial>
      <mass value="0.001"/>
      <inertia ixx="0.01" ixy="0.0" ixz="0.0" iyy="0.01" iyz="0.0" izz="0.01"/>
    </inertial>
    <collision>
      <geometry name="x01">
        <box size="0.050 0.038 0.032"/>
      </geometry>
    </collision>
  </link>
  <joint name="arm_l_0_box_bottom_joint" type="fixed">
    <origin rpy="0 1.57079632679 0" xyz="0.025 0 0"/>
    <parent link="arm_l_0_box_link"/>
    <child link="arm_l_0_box_bottom_link"/>
  </joint>
  <link name="arm_l_0_box_bottom_link">
    <inertial>
      <origin rpy="0 0 0" xyz="0 0 0"/>
      <mass value="0.0001"/>
      <inertia ixx="0.001" ixy="0.0" ixz="0.0" iyy="0.001" iyz="0.0" izz="0.001"/>
    </inertial>
    <visual>
      <origin rpy="0 0 0" xyz="0 0 0"/>
      <geometry>
        <cylinder length="0.001" radius="0.01"/>
      </geometry>
      <material name="mount"/>
    </visual>
  </link>
  <gazebo reference="arm_l_0_box_bottom_link">
    <material>Gazebo/Black</material>
  </gazebo>
  <joint name="arm_l_0_box_axel_joint" type="fixed">
    <origin rpy="1.57079632679 0 3.14159265359" xyz="-0.012 0.019 0"/>
    <parent link="arm_l_0_box_link"/>
    <child link="arm_l_0_box_axel_link"/>
  </joint>
  <link name="arm_l_0_box_axel_link">
    <inertial>
      <origin rpy="0 0 0" xyz="0 0 0"/>
      <mass value="0.0001"/>
      <inertia ixx="0.001" ixy="0.0" ixz="0.0" iyy="0.001" iyz="0.0" izz="0.001"/>
    </inertial>
    <visual>
      <origin rpy="0 0 0" xyz="0 0 0"/>
      <geometry>
        <cylinder length="0.001" radius="0.01"/>
      </geometry>
      <material name="mount"/>
    </visual>
  </link>
  <gazebo reference="arm_l_0_box_axel_link">
    <material>Gazebo/Black</material>
  </gazebo>
  <joint name="arm_l_0_box_joint" type="fixed">
    <origin rpy="1.57079632679 0 -1.57079632679" xyz="0 0 0.019"/>
    <parent link="arm_l_0_mount_link"/>
    <child link="arm_l_0_box_link"/>
  </joint>
  <link name="arm_l_0_axel_box_link">
    <visual>
      <geometry>
        <cylinder length="0.005" radius="0.011"/>
      </geometry>
      <material name="plastic_white"/>
    </visual>
    <inertial>
      <mass value="0.001"/>
      <inertia ixx="0.001" ixy="0.0" ixz="0.0" iyy="0.001" iyz="0.0" izz="0.001"/>
    </inertial>
    <collision>
      <geometry>
        <cylinder length="0.005" radius="0.011"/>
      </geometry>
    </collision>
  </link>
  <joint name="arm_l_0_axel_joint" type="fixed">
    <origin rpy="0 0 1.57079632679" xyz="0 0 0.0025"/>
    <parent link="arm_l_0_axel_box_link"/>
    <child link="arm_l_0_axel_link"/>
  </joint>
  <link name="arm_l_0_axel_link">
    <inertial>
      <origin rpy="0 0 0" xyz="0 0 0"/>
      <mass value="0.0001"/>
      <inertia ixx="0.001" ixy="0.0" ixz="0.0" iyy="0.001" iyz="0.0" izz="0.001"/>
    </inertial>
    <visual>
      <origin rpy="0 0 0" xyz="0 0 0"/>
      <geometry>
        <cylinder length="0.001" radius="0.01"/>
      </geometry>
      <material name="mount"/>
    </visual>
  </link>
  <gazebo reference="arm_l_0_axel_link">
    <material>Gazebo/Black</material>
  </gazebo>
  <joint name="arm_l_0_joint" type="revolute">
    <parent link="arm_l_0_box_axel_link"/>
    <child link="arm_l_0_axel_box_link"/>
    <origin rpy="0 0 0" xyz="0 0 0"/>
    <axis xyz="0 0 1"/>
    <limit effort="100" lower="3.14159265359" upper="3.14159265359" velocity="1"/>
    <dynamics damping="0.01" friction="0.01"/>
  </joint>
  <transmission name="arm_l_0_trans">
    <type>transmission_interface/SimpleTransmission</type>
    <joint name="arm_l_0_joint">
      <hardwareInterface>EffortJointInterface</hardwareInterface>
    </joint>
    <actuator name="arm_l_0_motor">
      <hardwareInterface>EffortJointInterface</hardwareInterface>
      <mechanicalReduction>1</mechanicalReduction>
    </actuator>
  </transmission>
  <gazebo reference="arm_l_0_box_link">
    <material>Gazebo/White</material>
  </gazebo>
  <gazebo reference="arm_l_0_box_axel_link">
    <material>Gazebo/White</material>
  </gazebo>
  <joint name="arm_l_1_mount_joint" type="fixed">
    <origin xyz="0 0 0"/>
    <parent link="arm_l_0_axel_link"/>
    <child link="arm_l_1_mount_link"/>
  </joint>
  <link name="arm_l_1_mount_link">
    <inertial>
      <origin rpy="0 0 0" xyz="0 0 0"/>
      <mass value="0.0001"/>
      <inertia ixx="0.001" ixy="0.0" ixz="0.0" iyy="0.001" iyz="0.0" izz="0.001"/>
    </inertial>
    <visual>
      <origin rpy="0 0 0" xyz="0 0 0"/>
      <geometry>
        <cylinder length="0.001" radius="0.01"/>
      </geometry>
      <material name="mount"/>
    </visual>
  </link>
  <gazebo reference="arm_l_1_mount_link">
    <material>Gazebo/Black</material>
  </gazebo>
  <link name="arm_l_1_box_link">
    <visual>
      <geometry name="x01mesh">
        <mesh filename="package://herkulex_description/meshes/x01_box_plain.stl" scale="0.001 0.001 0.001"/>
      </geometry>
      <material name="plastic_black"/>
      <origin rpy="3.14159265359 0 0" xyz="0 0 0"/>
    </visual>
    <inertial>
      <mass value="0.001"/>
      <inertia ixx="0.01" ixy="0.0" ixz="0.0" iyy="0.01" iyz="0.0" izz="0.01"/>
    </inertial>
    <collision>
      <geometry name="x01">
        <box size="0.050 0.038 0.032"/>
      </geometry>
    </collision>
  </link>
  <joint name="arm_l_1_box_back_joint" type="fixed">
    <origin rpy="1.57079632679 0 0" xyz="0 -0.019 0"/>
    <parent link="arm_l_1_box_link"/>
    <child link="arm_l_1_box_back_link"/>
  </joint>
  <link name="arm_l_1_box_back_link">
    <inertial>
      <origin rpy="0 0 0" xyz="0 0 0"/>
      <mass value="0.0001"/>
      <inertia ixx="0.001" ixy="0.0" ixz="0.0" iyy="0.001" iyz="0.0" izz="0.001"/>
    </inertial>
    <visual>
      <origin rpy="0 0 0" xyz="0 0 0"/>
      <geometry>
        <cylinder length="0.001" radius="0.01"/>
      </geometry>
      <material name="mount"/>
    </visual>
  </link>
  <gazebo reference="arm_l_1_box_back_link">
    <material>Gazebo/Black</material>
  </gazebo>
  <joint name="arm_l_1_box_axel_joint" type="fixed">
    <origin rpy="1.57079632679 0 3.14159265359" xyz="-0.012 0.019 0"/>
    <parent link="arm_l_1_box_link"/>
    <child link="arm_l_1_box_axel_link"/>
  </joint>
  <link name="arm_l_1_box_axel_link">
    <inertial>
      <origin rpy="0 0 0" xyz="0 0 0"/>
      <mass value="0.0001"/>
      <inertia ixx="0.001" ixy="0.0" ixz="0.0" iyy="0.001" iyz="0.0" izz="0.001"/>
    </inertial>
    <visual>
      <origin rpy="0 0 0" xyz="0 0 0"/>
      <geometry>
        <cylinder length="0.001" radius="0.01"/>
      </geometry>
      <material name="mount"/>
    </visual>
  </link>
  <gazebo reference="arm_l_1_box_axel_link">
    <material>Gazebo/Black</material>
  </gazebo>
  <joint name="arm_l_1_box_joint" type="fixed">
    <origin rpy="0 1.57079632679 0" xyz="0 0 0.025"/>
    <parent link="arm_l_1_mount_link"/>
    <child link="arm_l_1_box_link"/>
  </joint>
  <link name="arm_l_1_axel_box_link">
    <visual>
      <geometry>
        <cylinder length="0.005" radius="0.011"/>
      </geometry>
      <material name="plastic_white"/>
    </visual>
    <inertial>
      <mass value="0.001"/>
      <inertia ixx="0.001" ixy="0.0" ixz="0.0" iyy="0.001" iyz="0.0" izz="0.001"/>
    </inertial>
    <collision>
      <geometry>
        <cylinder length="0.005" radius="0.011"/>
      </geometry>
    </collision>
  </link>
  <joint name="arm_l_1_axel_joint" type="fixed">
    <origin rpy="0 0 1.57079632679" xyz="0 0 0.0025"/>
    <parent link="arm_l_1_axel_box_link"/>
    <child link="arm_l_1_axel_link"/>
  </joint>
  <link name="arm_l_1_axel_link">
    <inertial>
      <origin rpy="0 0 0" xyz="0 0 0"/>
      <mass value="0.0001"/>
      <inertia ixx="0.001" ixy="0.0" ixz="0.0" iyy="0.001" iyz="0.0" izz="0.001"/>
    </inertial>
    <visual>
      <origin rpy="0 0 0" xyz="0 0 0"/>
      <geometry>
        <cylinder length="0.001" radius="0.01"/>
      </geometry>
      <material name="mount"/>
    </visual>
  </link>
  <gazebo reference="arm_l_1_axel_link">
    <material>Gazebo/Black</material>
  </gazebo>
  <joint name="arm_l_1_joint" type="revolute">
    <parent link="arm_l_1_box_axel_link"/>
    <child link="arm_l_1_axel_box_link"/>
    <origin rpy="0 0 0" xyz="0 0 0"/>
    <axis xyz="0 0 1"/>
    <limit effort="100" lower="3.14159265359" upper="3.14159265359" velocity="1"/>
    <dynamics damping="0.01" friction="0.01"/>
  </joint>
  <transmission name="arm_l_1_trans">
    <type>transmission_interface/SimpleTransmission</type>
    <joint name="arm_l_1_joint">
      <hardwareInterface>EffortJointInterface</hardwareInterface>
    </joint>
    <actuator name="arm_l_1_motor">
      <hardwareInterface>EffortJointInterface</hardwareInterface>
      <mechanicalReduction>1</mechanicalReduction>
    </actuator>
  </transmission>
  <gazebo reference="arm_l_1_box_link">
    <material>Gazebo/White</material>
  </gazebo>
  <gazebo reference="arm_l_1_box_axel_link">
    <material>Gazebo/White</material>
  </gazebo>
  <joint name="arm_l_2_mount_joint" type="fixed">
    <origin xyz="0 0 0"/>
    <parent link="arm_l_1_axel_link"/>
    <child link="arm_l_2_mount_link"/>
  </joint>
  <link name="arm_l_2_mount_link">
    <inertial>
      <origin rpy="0 0 0" xyz="0 0 0"/>
      <mass value="0.0001"/>
      <inertia ixx="0.001" ixy="0.0" ixz="0.0" iyy="0.001" iyz="0.0" izz="0.001"/>
    </inertial>
    <visual>
      <origin rpy="0 0 0" xyz="0 0 0"/>
      <geometry>
        <cylinder length="0.001" radius="0.01"/>
      </geometry>
      <material name="mount"/>
    </visual>
  </link>
  <gazebo reference="arm_l_2_mount_link">
    <material>Gazebo/Black</material>
  </gazebo>
  <link name="arm_l_2_box_link">
    <visual>
      <geometry name="x01mesh">
        <mesh filename="package://herkulex_description/meshes/x01_box_plain.stl" scale="0.001 0.001 0.001"/>
      </geometry>
      <material name="plastic_black"/>
      <origin rpy="3.14159265359 0 0" xyz="0 0 0"/>
    </visual>
    <inertial>
      <mass value="0.001"/>
      <inertia ixx="0.01" ixy="0.0" ixz="0.0" iyy="0.01" iyz="0.0" izz="0.01"/>
    </inertial>
    <collision>
      <geometry name="x01">
        <box size="0.050 0.038 0.032"/>
      </geometry>
    </collision>
  </link>
  <joint name="arm_l_2_box_back_joint" type="fixed">
    <origin rpy="1.57079632679 0 0" xyz="0 -0.019 0"/>
    <parent link="arm_l_2_box_link"/>
    <child link="arm_l_2_box_back_link"/>
  </joint>
  <link name="arm_l_2_box_back_link">
    <inertial>
      <origin rpy="0 0 0" xyz="0 0 0"/>
      <mass value="0.0001"/>
      <inertia ixx="0.001" ixy="0.0" ixz="0.0" iyy="0.001" iyz="0.0" izz="0.001"/>
    </inertial>
    <visual>
      <origin rpy="0 0 0" xyz="0 0 0"/>
      <geometry>
        <cylinder length="0.001" radius="0.01"/>
      </geometry>
      <material name="mount"/>
    </visual>
  </link>
  <gazebo reference="arm_l_2_box_back_link">
    <material>Gazebo/Black</material>
  </gazebo>
  <joint name="arm_l_2_box_axel_joint" type="fixed">
    <origin rpy="1.57079632679 0 3.14159265359" xyz="-0.012 0.019 0"/>
    <parent link="arm_l_2_box_link"/>
    <child link="arm_l_2_box_axel_link"/>
  </joint>
  <link name="arm_l_2_box_axel_link">
    <inertial>
      <origin rpy="0 0 0" xyz="0 0 0"/>
      <mass value="0.0001"/>
      <inertia ixx="0.001" ixy="0.0" ixz="0.0" iyy="0.001" iyz="0.0" izz="0.001"/>
    </inertial>
    <visual>
      <origin rpy="0 0 0" xyz="0 0 0"/>
      <geometry>
        <cylinder length="0.001" radius="0.01"/>
      </geometry>
      <material name="mount"/>
    </visual>
  </link>
  <gazebo reference="arm_l_2_box_axel_link">
    <material>Gazebo/Black</material>
  </gazebo>
  <joint name="arm_l_2_box_joint" type="fixed">
    <origin rpy="0 1.57079632679 0" xyz="0 0 0.025"/>
    <parent link="arm_l_2_mount_link"/>
    <child link="arm_l_2_box_link"/>
  </joint>
  <link name="arm_l_2_axel_box_link">
    <visual>
      <geometry>
        <cylinder length="0.005" radius="0.011"/>
      </geometry>
      <material name="plastic_white"/>
    </visual>
    <inertial>
      <mass value="0.001"/>
      <inertia ixx="0.001" ixy="0.0" ixz="0.0" iyy="0.001" iyz="0.0" izz="0.001"/>
    </inertial>
    <collision>
      <geometry>
        <cylinder length="0.005" radius="0.011"/>
      </geometry>
    </collision>
  </link>
  <joint name="arm_l_2_axel_joint" type="fixed">
    <origin rpy="0 0 1.57079632679" xyz="0 0 0.0025"/>
    <parent link="arm_l_2_axel_box_link"/>
    <child link="arm_l_2_axel_link"/>
  </joint>
  <link name="arm_l_2_axel_link">
    <inertial>
      <origin rpy="0 0 0" xyz="0 0 0"/>
      <mass value="0.0001"/>
      <inertia ixx="0.001" ixy="0.0" ixz="0.0" iyy="0.001" iyz="0.0" izz="0.001"/>
    </inertial>
    <visual>
      <origin rpy="0 0 0" xyz="0 0 0"/>
      <geometry>
        <cylinder length="0.001" radius="0.01"/>
      </geometry>
      <material name="mount"/>
    </visual>
  </link>
  <gazebo reference="arm_l_2_axel_link">
    <material>Gazebo/Black</material>
  </gazebo>
  <joint name="arm_l_2_joint" type="revolute">
    <parent link="arm_l_2_box_axel_link"/>
    <child link="arm_l_2_axel_box_link"/>
    <origin rpy="0 0 0" xyz="0 0 0"/>
    <axis xyz="0 0 1"/>
    <limit effort="100" lower="3.14159265359" upper="3.14159265359" velocity="1"/>
    <dynamics damping="0.01" friction="0.01"/>
  </joint>
  <transmission name="arm_l_2_trans">
    <type>transmission_interface/SimpleTransmission</type>
    <joint name="arm_l_2_joint">
      <hardwareInterface>EffortJointInterface</hardwareInterface>
    </joint>
    <actuator name="arm_l_2_motor">
      <hardwareInterface>EffortJointInterface</hardwareInterface>
      <mechanicalReduction>1</mechanicalReduction>
    </actuator>
  </transmission>
  <gazebo reference="arm_l_2_box_link">
    <material>Gazebo/White</material>
  </gazebo>
  <gazebo reference="arm_l_2_box_axel_link">
    <material>Gazebo/White</material>
  </gazebo>
  <joint name="arm_l_3_mount_joint" type="fixed">
    <origin xyz="0 0 0"/>
    <parent link="arm_l_2_axel_link"/>
    <child link="arm_l_3_mount_link"/>
  </joint>
  <link name="arm_l_3_mount_link">
    <inertial>
      <origin rpy="0 0 0" xyz="0 0 0"/>
      <mass value="0.0001"/>
      <inertia ixx="0.001" ixy="0.0" ixz="0.0" iyy="0.001" iyz="0.0" izz="0.001"/>
    </inertial>
    <visual>
      <origin rpy="0 0 0" xyz="0 0 0"/>
      <geometry>
        <cylinder length="0.001" radius="0.01"/>
      </geometry>
      <material name="mount"/>
    </visual>
  </link>
  <gazebo reference="arm_l_3_mount_link">
    <material>Gazebo/Black</material>
  </gazebo>
  <link name="arm_l_3_box_link">
    <visual>
      <geometry name="x01mesh">
        <mesh filename="package://herkulex_description/meshes/x01_box_plain.stl" scale="0.001 0.001 0.001"/>
      </geometry>
      <material name="plastic_black"/>
      <origin rpy="3.14159265359 0 0" xyz="0 0 0"/>
    </visual>
    <inertial>
      <mass value="0.001"/>
      <inertia ixx="0.01" ixy="0.0" ixz="0.0" iyy="0.01" iyz="0.0" izz="0.01"/>
    </inertial>
    <collision>
      <geometry name="x01">
        <box size="0.050 0.038 0.032"/>
      </geometry>
    </collision>
  </link>
  <joint name="arm_l_3_box_back_joint" type="fixed">
    <origin rpy="1.57079632679 0 0" xyz="0 -0.019 0"/>
    <parent link="arm_l_3_box_link"/>
    <child link="arm_l_3_box_back_link"/>
  </joint>
  <link name="arm_l_3_box_back_link">
    <inertial>
      <origin rpy="0 0 0" xyz="0 0 0"/>
      <mass value="0.0001"/>
      <inertia ixx="0.001" ixy="0.0" ixz="0.0" iyy="0.001" iyz="0.0" izz="0.001"/>
    </inertial>
    <visual>
      <origin rpy="0 0 0" xyz="0 0 0"/>
      <geometry>
        <cylinder length="0.001" radius="0.01"/>
      </geometry>
      <material name="mount"/>
    </visual>
  </link>
  <gazebo reference="arm_l_3_box_back_link">
    <material>Gazebo/Black</material>
  </gazebo>
  <joint name="arm_l_3_box_axel_joint" type="fixed">
    <origin rpy="1.57079632679 0 3.14159265359" xyz="-0.012 0.019 0"/>
    <parent link="arm_l_3_box_link"/>
    <child link="arm_l_3_box_axel_link"/>
  </joint>
  <link name="arm_l_3_box_axel_link">
    <inertial>
      <origin rpy="0 0 0" xyz="0 0 0"/>
      <mass value="0.0001"/>
      <inertia ixx="0.001" ixy="0.0" ixz="0.0" iyy="0.001" iyz="0.0" izz="0.001"/>
    </inertial>
    <visual>
      <origin rpy="0 0 0" xyz="0 0 0"/>
      <geometry>
        <cylinder length="0.001" radius="0.01"/>
      </geometry>
      <material name="mount"/>
    </visual>
  </link>
  <gazebo reference="arm_l_3_box_axel_link">
    <material>Gazebo/Black</material>
  </gazebo>
  <joint name="arm_l_3_box_joint" type="fixed">
    <origin rpy="0 1.57079632679 0" xyz="0 0 0.025"/>
    <parent link="arm_l_3_mount_link"/>
    <child link="arm_l_3_box_link"/>
  </joint>
  <link name="arm_l_3_axel_box_link">
    <visual>
      <geometry>
        <cylinder length="0.005" radius="0.011"/>
      </geometry>
      <material name="plastic_white"/>
    </visual>
    <inertial>
      <mass value="0.001"/>
      <inertia ixx="0.001" ixy="0.0" ixz="0.0" iyy="0.001" iyz="0.0" izz="0.001"/>
    </inertial>
    <collision>
      <geometry>
        <cylinder length="0.005" radius="0.011"/>
      </geometry>
    </collision>
  </link>
  <joint name="arm_l_3_axel_joint" type="fixed">
    <origin rpy="0 0 1.57079632679" xyz="0 0 0.0025"/>
    <parent link="arm_l_3_axel_box_link"/>
    <child link="arm_l_3_axel_link"/>
  </joint>
  <link name="arm_l_3_axel_link">
    <inertial>
      <origin rpy="0 0 0" xyz="0 0 0"/>
      <mass value="0.0001"/>
      <inertia ixx="0.001" ixy="0.0" ixz="0.0" iyy="0.001" iyz="0.0" izz="0.001"/>
    </inertial>
    <visual>
      <origin rpy="0 0 0" xyz="0 0 0"/>
      <geometry>
        <cylinder length="0.001" radius="0.01"/>
      </geometry>
      <material name="mount"/>
    </visual>
  </link>
  <gazebo reference="arm_l_3_axel_link">
    <material>Gazebo/Black</material>
  </gazebo>
  <joint name="arm_l_3_joint" type="revolute">
    <parent link="arm_l_3_box_axel_link"/>
    <child link="arm_l_3_axel_box_link"/>
    <origin rpy="0 0 0" xyz="0 0 0"/>
    <axis xyz="0 0 1"/>
    <limit effort="100" lower="3.14159265359" upper="3.14159265359" velocity="1"/>
    <dynamics damping="0.01" friction="0.01"/>
  </joint>
  <transmission name="arm_l_3_trans">
    <type>transmission_interface/SimpleTransmission</type>
    <joint name="arm_l_3_joint">
      <hardwareInterface>EffortJointInterface</hardwareInterface>
    </joint>
    <actuator name="arm_l_3_motor">
      <hardwareInterface>EffortJointInterface</hardwareInterface>
      <mechanicalReduction>1</mechanicalReduction>
    </actuator>
  </transmission>
  <gazebo reference="arm_l_3_box_link">
    <material>Gazebo/White</material>
  </gazebo>
  <gazebo reference="arm_l_3_box_axel_link">
    <material>Gazebo/White</material>
  </gazebo>
  <joint name="arm_l_hand_joint" type="fixed">
    <origin rpy="0 0 0" xyz="0 0 0"/>
    <parent link="arm_l_3_axel_link"/>
    <child link="arm_l_hand_link"/>
  </joint>
  <link name="arm_l_hand_link">
    <inertial>
      <origin rpy="0 0 0" xyz="0 0 0"/>
      <mass value="0.0001"/>
      <inertia ixx="0.001" ixy="0.0" ixz="0.0" iyy="0.001" iyz="0.0" izz="0.001"/>
    </inertial>
    <visual>
      <origin rpy="0 0 0" xyz="0 0 0"/>
      <geometry>
        <cylinder length="0.001" radius="0.01"/>
      </geometry>
      <material name="mount"/>
    </visual>
  </link>
  <gazebo reference="arm_l_hand_link">
    <material>Gazebo/Black</material>
  </gazebo>
  <joint name="hand_l_mount_joint" type="fixed">
    <origin rpy="0 0 0" xyz="0 0 0"/>
    <parent link="arm_l_hand_link"/>
    <child link="hand_l_mount_link"/>
  </joint>
  <link name="hand_l_mount_link">
    <inertial>
      <origin rpy="0 0 0" xyz="0 0 0"/>
      <mass value="0.0001"/>
      <inertia ixx="0.001" ixy="0.0" ixz="0.0" iyy="0.001" iyz="0.0" izz="0.001"/>
    </inertial>
    <visual>
      <origin rpy="0 0 0" xyz="0 0 0"/>
      <geometry>
        <cylinder length="0.001" radius="0.01"/>
      </geometry>
      <material name="mount"/>
    </visual>
  </link>
  <gazebo reference="hand_l_mount_link">
    <material>Gazebo/Black</material>
  </gazebo>
  <joint name="hand_l_wrist_joint" type="fixed">
    <origin rpy="0 0 0" xyz="0 0 0.0275"/>
    <parent link="hand_l_mount_link"/>
    <child link="hand_l_link"/>
  </joint>
  <link name="hand_l_link">
    <inertial>
      <mass value="0.25"/>
      <inertia ixx="0.25" ixy="0.0" ixz="0.0" iyy="0.25" iyz="0.0" izz="0.25"/>
    </inertial>
    <visual>
      <origin rpy="0 0 0" xyz="0 0 0"/>
      <geometry>
        <cylinder length="0.055" radius="0.015"/>
      </geometry>
      <material name="skin"/>
    </visual>
    <collision>
      <origin rpy="0 0 0" xyz="0 0 0"/>
      <geometry>
        <cylinder length="0.055" radius="0.015"/>
      </geometry>
    </collision>
  </link>
  <joint name="hand_l_fingers_joint" type="fixed">
    <origin rpy="0 0 0" xyz="0 0 0.0275"/>
    <parent link="hand_l_link"/>
    <child link="hand_l_fingers_link"/>
  </joint>
  <link name="hand_l_fingers_link">
    <inertial>
      <origin rpy="0 0 0" xyz="0 0 0"/>
      <mass value="0.0001"/>
      <inertia ixx="0.001" ixy="0.0" ixz="0.0" iyy="0.001" iyz="0.0" izz="0.001"/>
    </inertial>
    <visual>
      <origin rpy="0 0 0" xyz="0 0 0"/>
      <geometry>
        <cylinder length="0.001" radius="0.01"/>
      </geometry>
      <material name="mount"/>
    </visual>
  </link>
  <gazebo reference="hand_l_fingers_link">
    <material>Gazebo/Black</material>
  </gazebo>
  <gazebo reference="hand_l_link">
    <material>Gazebo/Yellow</material>
  </gazebo>
  <joint name="neck_mount_joint" type="fixed">
    <origin rpy="0 0 0" xyz="0 0 0"/>
    <parent link="torso_top_link"/>
    <child link="neck_mount_link"/>
  </joint>
  <link name="neck_mount_link">
    <inertial>
      <origin rpy="0 0 0" xyz="0 0 0"/>
      <mass value="0.0001"/>
      <inertia ixx="0.001" ixy="0.0" ixz="0.0" iyy="0.001" iyz="0.0" izz="0.001"/>
    </inertial>
    <visual>
      <origin rpy="0 0 0" xyz="0 0 0"/>
      <geometry>
        <cylinder length="0.001" radius="0.01"/>
      </geometry>
      <material name="mount"/>
    </visual>
  </link>
  <gazebo reference="neck_mount_link">
    <material>Gazebo/Black</material>
  </gazebo>
  <joint name="neck_0_mount_joint" type="fixed">
    <origin xyz="0 0 0"/>
    <parent link="neck_mount_link"/>
    <child link="neck_0_mount_link"/>
  </joint>
  <link name="neck_0_mount_link">
    <inertial>
      <origin rpy="0 0 0" xyz="0 0 0"/>
      <mass value="0.0001"/>
      <inertia ixx="0.001" ixy="0.0" ixz="0.0" iyy="0.001" iyz="0.0" izz="0.001"/>
    </inertial>
    <visual>
      <origin rpy="0 0 0" xyz="0 0 0"/>
      <geometry>
        <cylinder length="0.001" radius="0.01"/>
      </geometry>
      <material name="mount"/>
    </visual>
  </link>
  <gazebo reference="neck_0_mount_link">
    <material>Gazebo/Black</material>
  </gazebo>
  <link name="neck_0_box_link">
    <visual>
      <geometry name="x01mesh">
        <mesh filename="package://herkulex_description/meshes/x01_box_plain.stl" scale="0.001 0.001 0.001"/>
      </geometry>
      <material name="plastic_black"/>
      <origin rpy="3.14159265359 0 0" xyz="0 0 0"/>
    </visual>
    <inertial>
      <mass value="0.001"/>
      <inertia ixx="0.01" ixy="0.0" ixz="0.0" iyy="0.01" iyz="0.0" izz="0.01"/>
    </inertial>
    <collision>
      <geometry name="x01">
        <box size="0.050 0.038 0.032"/>
      </geometry>
    </collision>
  </link>
  <joint name="neck_0_box_bottom_joint" type="fixed">
    <origin rpy="0 1.57079632679 0" xyz="0.025 0 0"/>
    <parent link="neck_0_box_link"/>
    <child link="neck_0_box_bottom_link"/>
  </joint>
  <link name="neck_0_box_bottom_link">
    <inertial>
      <origin rpy="0 0 0" xyz="0 0 0"/>
      <mass value="0.0001"/>
      <inertia ixx="0.001" ixy="0.0" ixz="0.0" iyy="0.001" iyz="0.0" izz="0.001"/>
    </inertial>
    <visual>
      <origin rpy="0 0 0" xyz="0 0 0"/>
      <geometry>
        <cylinder length="0.001" radius="0.01"/>
      </geometry>
      <material name="mount"/>
    </visual>
  </link>
  <gazebo reference="neck_0_box_bottom_link">
    <material>Gazebo/Black</material>
  </gazebo>
  <joint name="neck_0_box_axel_joint" type="fixed">
    <origin rpy="1.57079632679 0 3.14159265359" xyz="-0.012 0.019 0"/>
    <parent link="neck_0_box_link"/>
    <child link="neck_0_box_axel_link"/>
  </joint>
  <link name="neck_0_box_axel_link">
    <inertial>
      <origin rpy="0 0 0" xyz="0 0 0"/>
      <mass value="0.0001"/>
      <inertia ixx="0.001" ixy="0.0" ixz="0.0" iyy="0.001" iyz="0.0" izz="0.001"/>
    </inertial>
    <visual>
      <origin rpy="0 0 0" xyz="0 0 0"/>
      <geometry>
        <cylinder length="0.001" radius="0.01"/>
      </geometry>
      <material name="mount"/>
    </visual>
  </link>
  <gazebo reference="neck_0_box_axel_link">
    <material>Gazebo/Black</material>
  </gazebo>
  <joint name="neck_0_box_joint" type="fixed">
    <origin rpy="1.57079632679 0 -1.57079632679" xyz="0 0 0.019"/>
    <parent link="neck_0_mount_link"/>
    <child link="neck_0_box_link"/>
  </joint>
  <link name="neck_0_axel_box_link">
    <visual>
      <geometry>
        <cylinder length="0.005" radius="0.011"/>
      </geometry>
      <material name="plastic_white"/>
    </visual>
    <inertial>
      <mass value="0.001"/>
      <inertia ixx="0.001" ixy="0.0" ixz="0.0" iyy="0.001" iyz="0.0" izz="0.001"/>
    </inertial>
    <collision>
      <geometry>
        <cylinder length="0.005" radius="0.011"/>
      </geometry>
    </collision>
  </link>
  <joint name="neck_0_axel_joint" type="fixed">
    <origin rpy="0 0 1.57079632679" xyz="0 0 0.0025"/>
    <parent link="neck_0_axel_box_link"/>
    <child link="neck_0_axel_link"/>
  </joint>
  <link name="neck_0_axel_link">
    <inertial>
      <origin rpy="0 0 0" xyz="0 0 0"/>
      <mass value="0.0001"/>
      <inertia ixx="0.001" ixy="0.0" ixz="0.0" iyy="0.001" iyz="0.0" izz="0.001"/>
    </inertial>
    <visual>
      <origin rpy="0 0 0" xyz="0 0 0"/>
      <geometry>
        <cylinder length="0.001" radius="0.01"/>
      </geometry>
      <material name="mount"/>
    </visual>
  </link>
  <gazebo reference="neck_0_axel_link">
    <material>Gazebo/Black</material>
  </gazebo>
  <joint name="neck_0_joint" type="revolute">
    <parent link="neck_0_box_axel_link"/>
    <child link="neck_0_axel_box_link"/>
    <origin rpy="0 0 0" xyz="0 0 0"/>
    <axis xyz="0 0 1"/>
    <limit effort="100" lower="3.14159265359" upper="3.14159265359" velocity="1"/>
    <dynamics damping="0.01" friction="0.01"/>
  </joint>
  <transmission name="neck_0_trans">
    <type>transmission_interface/SimpleTransmission</type>
    <joint name="neck_0_joint">
      <hardwareInterface>EffortJointInterface</hardwareInterface>
    </joint>
    <actuator name="neck_0_motor">
      <hardwareInterface>EffortJointInterface</hardwareInterface>
      <mechanicalReduction>1</mechanicalReduction>
    </actuator>
  </transmission>
  <gazebo reference="neck_0_box_link">
    <material>Gazebo/White</material>
  </gazebo>
  <gazebo reference="neck_0_box_axel_link">
    <material>Gazebo/White</material>
  </gazebo>
  <joint name="neck_1_mount_joint" type="fixed">
    <origin rpy="0 0 3.14159265359" xyz="0 0 0"/>
    <parent link="neck_0_axel_link"/>
    <child link="neck_1_mount_link"/>
  </joint>
  <link name="neck_1_mount_link">
    <inertial>
      <origin rpy="0 0 0" xyz="0 0 0"/>
      <mass value="0.0001"/>
      <inertia ixx="0.001" ixy="0.0" ixz="0.0" iyy="0.001" iyz="0.0" izz="0.001"/>
    </inertial>
    <visual>
      <origin rpy="0 0 0" xyz="0 0 0"/>
      <geometry>
        <cylinder length="0.001" radius="0.01"/>
      </geometry>
      <material name="mount"/>
    </visual>
  </link>
  <gazebo reference="neck_1_mount_link">
    <material>Gazebo/Black</material>
  </gazebo>
  <link name="neck_1_box_link">
    <visual>
      <geometry name="x01mesh">
        <mesh filename="package://herkulex_description/meshes/x01_box_plain.stl" scale="0.001 0.001 0.001"/>
      </geometry>
      <material name="plastic_black"/>
      <origin rpy="3.14159265359 0 0" xyz="0 0 0"/>
    </visual>
    <inertial>
      <mass value="0.001"/>
      <inertia ixx="0.01" ixy="0.0" ixz="0.0" iyy="0.01" iyz="0.0" izz="0.01"/>
    </inertial>
    <collision>
      <geometry name="x01">
        <box size="0.050 0.038 0.032"/>
      </geometry>
    </collision>
  </link>
  <joint name="neck_1_box_back_joint" type="fixed">
    <origin rpy="1.57079632679 0 0" xyz="0 -0.019 0"/>
    <parent link="neck_1_box_link"/>
    <child link="neck_1_box_back_link"/>
  </joint>
  <link name="neck_1_box_back_link">
    <inertial>
      <origin rpy="0 0 0" xyz="0 0 0"/>
      <mass value="0.0001"/>
      <inertia ixx="0.001" ixy="0.0" ixz="0.0" iyy="0.001" iyz="0.0" izz="0.001"/>
    </inertial>
    <visual>
      <origin rpy="0 0 0" xyz="0 0 0"/>
      <geometry>
        <cylinder length="0.001" radius="0.01"/>
      </geometry>
      <material name="mount"/>
    </visual>
  </link>
  <gazebo reference="neck_1_box_back_link">
    <material>Gazebo/Black</material>
  </gazebo>
  <joint name="neck_1_box_axel_joint" type="fixed">
    <origin rpy="1.57079632679 0 3.14159265359" xyz="-0.012 0.019 0"/>
    <parent link="neck_1_box_link"/>
    <child link="neck_1_box_axel_link"/>
  </joint>
  <link name="neck_1_box_axel_link">
    <inertial>
      <origin rpy="0 0 0" xyz="0 0 0"/>
      <mass value="0.0001"/>
      <inertia ixx="0.001" ixy="0.0" ixz="0.0" iyy="0.001" iyz="0.0" izz="0.001"/>
    </inertial>
    <visual>
      <origin rpy="0 0 0" xyz="0 0 0"/>
      <geometry>
        <cylinder length="0.001" radius="0.01"/>
      </geometry>
      <material name="mount"/>
    </visual>
  </link>
  <gazebo reference="neck_1_box_axel_link">
    <material>Gazebo/Black</material>
  </gazebo>
  <joint name="neck_1_box_joint" type="fixed">
    <origin rpy="0 1.57079632679 0" xyz="0 0 0.025"/>
    <parent link="neck_1_mount_link"/>
    <child link="neck_1_box_link"/>
  </joint>
  <link name="neck_1_axel_box_link">
    <visual>
      <geometry>
        <cylinder length="0.005" radius="0.011"/>
      </geometry>
      <material name="plastic_white"/>
    </visual>
    <inertial>
      <mass value="0.001"/>
      <inertia ixx="0.001" ixy="0.0" ixz="0.0" iyy="0.001" iyz="0.0" izz="0.001"/>
    </inertial>
    <collision>
      <geometry>
        <cylinder length="0.005" radius="0.011"/>
      </geometry>
    </collision>
  </link>
  <joint name="neck_1_axel_joint" type="fixed">
    <origin rpy="0 0 1.57079632679" xyz="0 0 0.0025"/>
    <parent link="neck_1_axel_box_link"/>
    <child link="neck_1_axel_link"/>
  </joint>
  <link name="neck_1_axel_link">
    <inertial>
      <origin rpy="0 0 0" xyz="0 0 0"/>
      <mass value="0.0001"/>
      <inertia ixx="0.001" ixy="0.0" ixz="0.0" iyy="0.001" iyz="0.0" izz="0.001"/>
    </inertial>
    <visual>
      <origin rpy="0 0 0" xyz="0 0 0"/>
      <geometry>
        <cylinder length="0.001" radius="0.01"/>
      </geometry>
      <material name="mount"/>
    </visual>
  </link>
  <gazebo reference="neck_1_axel_link">
    <material>Gazebo/Black</material>
  </gazebo>
  <joint name="neck_1_joint" type="revolute">
    <parent link="neck_1_box_axel_link"/>
    <child link="neck_1_axel_box_link"/>
    <origin rpy="0 0 0" xyz="0 0 0"/>
    <axis xyz="0 0 1"/>
    <limit effort="100" lower="3.14159265359" upper="3.14159265359" velocity="1"/>
    <dynamics damping="0.01" friction="0.01"/>
  </joint>
  <transmission name="neck_1_trans">
    <type>transmission_interface/SimpleTransmission</type>
    <joint name="neck_1_joint">
      <hardwareInterface>EffortJointInterface</hardwareInterface>
    </joint>
    <actuator name="neck_1_motor">
      <hardwareInterface>EffortJointInterface</hardwareInterface>
      <mechanicalReduction>1</mechanicalReduction>
    </actuator>
  </transmission>
  <gazebo reference="neck_1_box_link">
    <material>Gazebo/White</material>
  </gazebo>
  <gazebo reference="neck_1_box_axel_link">
    <material>Gazebo/White</material>
  </gazebo>
  <joint name="neck_top_mount_joint" type="fixed">
    <origin rpy="0 0 0" xyz="0 0 0"/>
    <parent link="neck_1_axel_link"/>
    <child link="neck_top_mount_link"/>
  </joint>
  <link name="neck_top_mount_link">
    <inertial>
      <origin rpy="0 0 0" xyz="0 0 0"/>
      <mass value="0.0001"/>
      <inertia ixx="0.001" ixy="0.0" ixz="0.0" iyy="0.001" iyz="0.0" izz="0.001"/>
    </inertial>
    <visual>
      <origin rpy="0 0 0" xyz="0 0 0"/>
      <geometry>
        <cylinder length="0.001" radius="0.01"/>
      </geometry>
      <material name="mount"/>
    </visual>
  </link>
  <gazebo reference="neck_top_mount_link">
    <material>Gazebo/Black</material>
  </gazebo>
  <link name="neck_top_mesh_link">
    <visual>
      <geometry name="mount_mesh">
        <mesh filename="package://herkulex_description/meshes/mount.stl" scale="0.001 0.001 0.001"/>
      </geometry>
      <material name="plastic_green"/>
    </visual>
    <inertial>
      <mass value="0.005"/>
      <inertia ixx="0.001" ixy="0.0" ixz="0.0" iyy="0.001" iyz="0.0" izz="0.001"/>
    </inertial>
  </link>
  <joint name="neck_top_mesh_joint" type="fixed">
    <parent link="neck_top_mount_link"/>
    <child link="neck_top_mesh_link"/>
    <origin rpy="3.14159265359 0 0" xyz="0 0 -0.0205"/>
  </joint>
  <joint name="neck_top_joint" type="fixed">
    <origin rpy="1.57079632679 0 0" xyz="0 -0.027 0"/>
    <parent link="neck_top_mesh_link"/>
    <child link="neck_top_link"/>
  </joint>
  <link name="neck_top_link">
    <inertial>
      <origin rpy="0 0 0" xyz="0 0 0"/>
      <mass value="0.0001"/>
      <inertia ixx="0.001" ixy="0.0" ixz="0.0" iyy="0.001" iyz="0.0" izz="0.001"/>
    </inertial>
    <visual>
      <origin rpy="0 0 0" xyz="0 0 0"/>
      <geometry>
        <cylinder length="0.001" radius="0.01"/>
      </geometry>
      <material name="mount"/>
    </visual>
  </link>
  <gazebo reference="neck_top_link">
    <material>Gazebo/Black</material>
  </gazebo>
  <gazebo reference="neck_top_mesh_link">
    <material>Gazebo/Green</material>
  </gazebo>
  <joint name="head_mount_joint" type="fixed">
    <origin rpy="0 0 0" xyz="0 0 0.1"/>
    <parent link="neck_top_link"/>
    <child link="head_mount_link"/>
  </joint>
  <link name="head_mount_link">
    <inertial>
      <origin rpy="0 0 0" xyz="0 0 0"/>
      <mass value="0.0001"/>
      <inertia ixx="0.001" ixy="0.0" ixz="0.0" iyy="0.001" iyz="0.0" izz="0.001"/>
    </inertial>
    <visual>
      <origin rpy="0 0 0" xyz="0 0 0"/>
      <geometry>
        <cylinder length="0.001" radius="0.01"/>
      </geometry>
      <material name="mount"/>
    </visual>
  </link>
  <gazebo reference="head_mount_link">
    <material>Gazebo/Black</material>
  </gazebo>
  <joint name="head_joint" type="fixed">
    <origin rpy="0 0 0" xyz="0 0.03 0"/>
    <parent link="head_mount_link"/>
    <child link="head_link"/>
  </joint>
  <link name="head_link">
    <visual>
      <geometry>
        <sphere radius="0.05"/>
      </geometry>
      <material name="skin"/>
    </visual>
    <collision>
      <geometry>
        <sphere radius="0.05"/>
      </geometry>
    </collision>
  </link>
  <gazebo reference="head_link">
    <material>Gazebo/Yellow</material>
  </gazebo>
  <!-- ros_control plugin -->
  <gazebo>
    <plugin filename="libgazebo_ros_control.so" name="gazebo_ros_control">
      <robotNamespace>/kaspar</robotNamespace>
      <robotSimType>gazebo_ros_control/DefaultRobotHWSim</robotSimType>
    </plugin>
  </gazebo>
</robot>
