<?xml version="1.0"?>
<robot name="kaspar" xmlns:xacro="http://www.ros.org/wiki/xacro">

	<!-- Constants for robot dimensions -->
	<xacro:property name="PI" value="3.1415926535897931" />
	<xacro:property name="mass" value="10" />

	<!-- Import joint description -->
	<xacro:include filename="$(find dynamixel_description)/urdf/dynamixel_ax12.xacro" />
	<xacro:include filename="$(find dynamixel_description)/urdf/fp04_02.xacro" />

	<!-- Import individual part macros -->
	<xacro:include filename="$(find kaspar_description)/urdf/kaspar_arm.xacro" />
	<xacro:include filename="$(find kaspar_description)/urdf/kaspar_base.xacro" />
	<xacro:include filename="$(find kaspar_description)/urdf/kaspar_head.xacro" />
	<xacro:include filename="$(find kaspar_description)/urdf/kaspar_torso.xacro" />
	
	<xacro:include filename="$(find kaspar_description)/urdf/kaspar_mount.xacro" />
	<xacro:include filename="$(find kaspar_description)/urdf/materials.xacro" />

	<!-- Used for fixing robot in the world -->
	<link name="world_link" />

	<xacro:base_v0 name="base" parent="world">
		<origin rpy="0 0 0" xyz="0 0 0" />
	</xacro:base_v0>
	<xacro:leg_v0 name="leg_l" parent="base_leg_l">
		<origin rpy="0 0 0" xyz="0 0 0" />
	</xacro:leg_v0>
	<xacro:leg_v0 name="leg_r" parent="base_leg_r">
		<origin rpy="0 0 0" xyz="0 0 0" />
	</xacro:leg_v0>

	<joint name="base_torso_joint" type="revolute">
		<parent link="base_top_link" />
		<child link="base_torso_joint_link" />
		<axis xyz="0 0 1" />
		<limit effort="0" lower="-1.5707" upper="1.5707" velocity="1" />
	</joint>
	<link name="base_torso_joint_link" />

	<xacro:torso_v0 name="torso" parent="base_torso_joint">
		<origin rpy="0 0 0" xyz="0 0 0" />
	</xacro:torso_v0>
</robot>
