<?xml version="1.0" ?>
<!-- =================================================================================== -->
<!-- |    This document was autogenerated by xacro from kaspar.xacro                   | -->
<!-- |    EDITING THIS FILE BY HAND IS NOT RECOMMENDED                                 | -->
<!-- =================================================================================== -->
<robot name="kaspar" xmlns:controller="http://playerstage.sourceforge.net/gazebo/xmlschema/#controller" xmlns:interface="http://playerstage.sourceforge.net/gazebo/xmlschema/#interface" xmlns:sensor="http://playerstage.sourceforge.net/gazebo/xmlschema/#sensor" xmlns:xacro="http://www.ros.org/wiki/xacro">
  <!-- Constants for robot dimensions -->
  <!-- Import joint description -->
  <!-- Import individual part macros -->
  <material name="mount">
    <color rgba="0.08 0.08 0.08 1.0"/>
  </material>
  <material name="black">
    <color rgba="0.0 0.0 0.0 1.0"/>
  </material>
  <material name="blue">
    <color rgba="0.0 0.0 0.8 1.0"/>
  </material>
  <material name="green">
    <color rgba="0.0 0.8 0.0 1.0"/>
  </material>
  <material name="grey">
    <color rgba="0.2 0.2 0.2 1.0"/>
  </material>
  <material name="orange">
    <color rgba="1.0 0.423529411765 0.0392156862745 1.0"/>
  </material>
  <material name="brown">
    <color rgba="0.870588235294 0.811764705882 0.764705882353 1.0"/>
  </material>
  <material name="red">
    <color rgba="0.8 0.0 0.0 1.0"/>
  </material>
  <material name="white">
    <color rgba="1.0 1.0 1.0 1.0"/>
  </material>
  <!-- Used for fixing robot in the world -->
  <link name="world_link"/>
  <joint name="base_joint" type="fixed">
    <origin rpy="0 0 0" xyz="0 0 0"/>
    <parent link="world_link"/>
    <child link="base_link"/>
  </joint>
  <link name="base_link">
    <inertial>
      <mass value="5"/>
      <origin rpy="0 0 0" xyz="0 0 0.05"/>
      <inertia ixx="0.001" ixy="0.0" ixz="0.0" iyy="0.001" iyz="0.0" izz="0.001"/>
    </inertial>
    <visual>
      <origin rpy="0 0 0" xyz="0 0 0.05"/>
      <geometry>
        <cylinder length="0.15" radius="0.05"/>
      </geometry>
      <material name="white"/>
    </visual>
    <collision>
      <origin rpy="0 0 0" xyz="0 0 0.05"/>
      <geometry>
        <cylinder length="0.15" radius="0.05"/>
      </geometry>
    </collision>
  </link>
  <joint name="base_top_joint" type="fixed">
    <origin rpy="0 0 0" xyz="0 0 0.15"/>
    <parent link="base_link"/>
    <child link="base_top_link"/>
  </joint>
  <link name="base_top_link">
    <inertial>
      <origin rpy="0 0 0" xyz="0 0 0.0005"/>
      <mass value="0.0001"/>
      <inertia ixx="0.001" ixy="0.0" ixz="0.0" iyy="0.001" iyz="0.0" izz="0.001"/>
    </inertial>
    <visual>
      <origin rpy="0 0 0" xyz="0 0 0.0005"/>
      <geometry>
        <box size="0.02 0.02 0.001"/>
      </geometry>
      <material name="mount"/>
    </visual>
  </link>
  <gazebo reference="base_top_link">
    <material>Gazebo/Black</material>
  </gazebo>
  <joint name="base_leg_l_joint" type="fixed">
    <origin rpy="0 0 0.23" xyz="0.075 0.06 0"/>
    <parent link="base_link"/>
    <child link="base_leg_l_link"/>
  </joint>
  <link name="base_leg_l_link">
    <inertial>
      <origin rpy="0 0 0" xyz="0 0 0.0005"/>
      <mass value="0.0001"/>
      <inertia ixx="0.001" ixy="0.0" ixz="0.0" iyy="0.001" iyz="0.0" izz="0.001"/>
    </inertial>
    <visual>
      <origin rpy="0 0 0" xyz="0 0 0.0005"/>
      <geometry>
        <box size="0.02 0.02 0.001"/>
      </geometry>
      <material name="mount"/>
    </visual>
  </link>
  <gazebo reference="base_leg_l_link">
    <material>Gazebo/Black</material>
  </gazebo>
  <joint name="base_leg_r_joint" type="fixed">
    <origin rpy="0 0 -0.23" xyz="0.075 -0.06 0"/>
    <parent link="base_link"/>
    <child link="base_leg_r_link"/>
  </joint>
  <link name="base_leg_r_link">
    <inertial>
      <origin rpy="0 0 0" xyz="0 0 0.0005"/>
      <mass value="0.0001"/>
      <inertia ixx="0.001" ixy="0.0" ixz="0.0" iyy="0.001" iyz="0.0" izz="0.001"/>
    </inertial>
    <visual>
      <origin rpy="0 0 0" xyz="0 0 0.0005"/>
      <geometry>
        <box size="0.02 0.02 0.001"/>
      </geometry>
      <material name="mount"/>
    </visual>
  </link>
  <gazebo reference="base_leg_r_link">
    <material>Gazebo/Black</material>
  </gazebo>
  <gazebo reference="base_link">
    <material>Gazebo/White</material>
  </gazebo>
  <joint name="leg_l_joint" type="fixed">
    <origin rpy="0 0 0" xyz="0 0 0"/>
    <parent link="base_leg_l_link"/>
    <child link="leg_l_link"/>
  </joint>
  <link name="leg_l_link">
    <inertial>
      <mass value="0.1"/>
      <inertia ixx="0.001" ixy="0.0" ixz="0.0" iyy="0.001" iyz="0.0" izz="0.001"/>
    </inertial>
    <visual>
      <origin rpy="0 1.5707 0"/>
      <geometry>
        <cylinder length="0.15" radius="0.03"/>
      </geometry>
      <material name="white"/>
    </visual>
    <collision>
      <origin rpy="0 1.5707 0"/>
      <geometry>
        <cylinder length="0.15" radius="0.03"/>
      </geometry>
    </collision>
  </link>
  <gazebo reference="leg_l_link">
    <material>Gazebo/White</material>
  </gazebo>
  <joint name="leg_r_joint" type="fixed">
    <origin rpy="0 0 0" xyz="0 0 0"/>
    <parent link="base_leg_r_link"/>
    <child link="leg_r_link"/>
  </joint>
  <link name="leg_r_link">
    <inertial>
      <mass value="0.1"/>
      <inertia ixx="0.001" ixy="0.0" ixz="0.0" iyy="0.001" iyz="0.0" izz="0.001"/>
    </inertial>
    <visual>
      <origin rpy="0 1.5707 0"/>
      <geometry>
        <cylinder length="0.15" radius="0.03"/>
      </geometry>
      <material name="white"/>
    </visual>
    <collision>
      <origin rpy="0 1.5707 0"/>
      <geometry>
        <cylinder length="0.15" radius="0.03"/>
      </geometry>
    </collision>
  </link>
  <gazebo reference="leg_r_link">
    <material>Gazebo/White</material>
  </gazebo>
  <joint name="base_torso_joint" type="revolute">
    <parent link="base_top_link"/>
    <child link="base_torso_joint_link"/>
    <axis xyz="1 0 0"/>
    <limit effort="0" lower="-1.5707" upper="1.5707" velocity="1"/>
  </joint>
  <link name="base_torso_joint_link"/>
  <joint name="torso_joint" type="fixed">
    <origin rpy="0 0 0" xyz="0 0 0"/>
    <parent link="base_torso_joint_link"/>
    <child link="torso_link"/>
  </joint>
  <link name="torso_link">
    <inertial>
      <mass value="5"/>
      <origin rpy="0 0 0" xyz="0 0 0.05"/>
      <inertia ixx="0.001" ixy="0.0" ixz="0.0" iyy="0.001" iyz="0.0" izz="0.001"/>
    </inertial>
    <visual>
      <origin rpy="0 0 0" xyz="0 0 0.05"/>
      <geometry>
        <cylinder length="0.15" radius="0.06"/>
      </geometry>
      <material name="white"/>
    </visual>
    <collision>
      <origin rpy="0 0 0" xyz="0 0 0.05"/>
      <geometry>
        <cylinder length="0.15" radius="0.06"/>
      </geometry>
    </collision>
  </link>
  <joint name="torso_top_joint" type="fixed">
    <origin rpy="0 0 0" xyz="0 0 0.25"/>
    <parent link="torso_link"/>
    <child link="torso_top_link"/>
  </joint>
  <link name="torso_top_link">
    <inertial>
      <origin rpy="0 0 0" xyz="0 0 0.0005"/>
      <mass value="0.0001"/>
      <inertia ixx="0.001" ixy="0.0" ixz="0.0" iyy="0.001" iyz="0.0" izz="0.001"/>
    </inertial>
    <visual>
      <origin rpy="0 0 0" xyz="0 0 0.0005"/>
      <geometry>
        <box size="0.02 0.02 0.001"/>
      </geometry>
      <material name="mount"/>
    </visual>
  </link>
  <gazebo reference="torso_top_link">
    <material>Gazebo/Black</material>
  </gazebo>
  <joint name="torso_arm_l_joint" type="fixed">
    <origin rpy="-1.57079 0 0" xyz="0 0.06 0.22"/>
    <parent link="torso_link"/>
    <child link="torso_arm_l_link"/>
  </joint>
  <link name="torso_arm_l_link">
    <inertial>
      <origin rpy="0 0 0" xyz="0 0 0.0005"/>
      <mass value="0.0001"/>
      <inertia ixx="0.001" ixy="0.0" ixz="0.0" iyy="0.001" iyz="0.0" izz="0.001"/>
    </inertial>
    <visual>
      <origin rpy="0 0 0" xyz="0 0 0.0005"/>
      <geometry>
        <box size="0.02 0.02 0.001"/>
      </geometry>
      <material name="mount"/>
    </visual>
  </link>
  <gazebo reference="torso_arm_l_link">
    <material>Gazebo/Black</material>
  </gazebo>
  <joint name="torso_arm_r_joint" type="fixed">
    <origin rpy="1.57079 0 0" xyz="0 -0.06 0.22"/>
    <parent link="torso_link"/>
    <child link="torso_arm_r_link"/>
  </joint>
  <link name="torso_arm_r_link">
    <inertial>
      <origin rpy="0 0 0" xyz="0 0 0.0005"/>
      <mass value="0.0001"/>
      <inertia ixx="0.001" ixy="0.0" ixz="0.0" iyy="0.001" iyz="0.0" izz="0.001"/>
    </inertial>
    <visual>
      <origin rpy="0 0 0" xyz="0 0 0.0005"/>
      <geometry>
        <box size="0.02 0.02 0.001"/>
      </geometry>
      <material name="mount"/>
    </visual>
  </link>
  <gazebo reference="torso_arm_r_link">
    <material>Gazebo/Black</material>
  </gazebo>
  <gazebo reference="torso_link">
    <material>Gazebo/White</material>
  </gazebo>
</robot>
