<?xml version="1.0"?>
<robot xmlns:xacro="http://www.ros.org/wiki/xacro">

	<xacro:macro name="torso_v0" params="name parent *origin">
		<xacro:mount_point name="${name}_mount" parent="${parent}">
			<insert_block name="origin" />
		</xacro:mount_point>

		<joint name="${name}_joint" type="revolute">
			<origin xyz="0 0 0" rpy="0 0 0" />
			<parent link="${name}_mount_link" />
			<child link="${name}_link" />
			<axis xyz="0 0 1" />
			<limit effort="0" lower="-1.5707" upper="1.5707" velocity="1" />
			<dynamics friction="0.01" damping="0.01" />
		</joint>
		<link name="${name}_link">
			<inertial>
				<origin xyz="0 0 0.08" rpy="0 0 0" />
				<mass value="0.001" />
				<inertia ixx="0.01" ixy="0.0" ixz="0.0" iyy="0.01" iyz="0.0" izz="0.01" />
			</inertial>
			<visual>
				<origin xyz="0 0 0.08" rpy="0 0 0" />
				<geometry>
					<cylinder length="0.15" radius="0.08" />
				</geometry>
				<material name="shell" />
			</visual>
			<collision>
				<origin xyz="0 0 0.08" rpy="0 0 0" />
				<geometry>
					<cylinder length="0.15" radius="0.08" />
				</geometry>
			</collision>
		</link>

		<xacro:mount_point name="${name}_top" parent="${name}">
			<origin rpy="0 0 0" xyz="0 0 0.155" />
		</xacro:mount_point>
		<xacro:mount_point name="${name}_arm_l" parent="${name}">
			<origin rpy="-${PI / 2} -${PI / 2} 0" xyz="0 0.08 0.12" />
		</xacro:mount_point>
		<xacro:mount_point name="${name}_arm_r" parent="${name}">
			<origin rpy="${PI / 2} ${PI / 2} 0" xyz="0 -0.08 0.12" />
		</xacro:mount_point>

		<!-- Gazebo Config -->
		<transmission name="${name}_trans">
			<type>transmission_interface/SimpleTransmission</type>
			<joint name="${name}_joint">
				<hardwareInterface>EffortJointInterface</hardwareInterface>
			</joint>
			<actuator name="${name}_motor">
				<hardwareInterface>EffortJointInterface</hardwareInterface>
				<mechanicalReduction>1</mechanicalReduction>
			</actuator>
		</transmission>
		<gazebo reference="${name}_link">
			<material>Gazebo/White</material>
		</gazebo>
	</xacro:macro>
</robot>