<?xml version="1.0" ?>
<!-- =================================================================================== -->
<!-- |    This document was autogenerated by xacro from kaspar.xacro                   | -->
<!-- |    EDITING THIS FILE BY HAND IS NOT RECOMMENDED                                 | -->
<!-- =================================================================================== -->
<robot name="kaspar" xmlns:controller="http://playerstage.sourceforge.net/gazebo/xmlschema/#controller" xmlns:interface="http://playerstage.sourceforge.net/gazebo/xmlschema/#interface" xmlns:sensor="http://playerstage.sourceforge.net/gazebo/xmlschema/#sensor" xmlns:xacro="http://www.ros.org/wiki/xacro">
  <!-- Constants for robot dimensions -->
  <!-- Import joint description -->
  <!-- Import individual part macros -->
  <material name="trousers">
    <color rgba="0.0 0.0 0.8 1.0"/>
  </material>
  <material name="shell">
    <color rgba="1.0 1.0 1.0 0.25"/>
  </material>
  <material name="mount">
    <color rgba="0.2 0.2 0.2 0.75"/>
  </material>
  <material name="skin">
    <color rgba="1.0 0.850980392157 0.0588235294118 0.95"/>
  </material>
  <material name="black">
    <color rgba="0.0 0.0 0.0 1.0"/>
  </material>
  <material name="blue">
    <color rgba="0.0 0.0 0.8 1.0"/>
  </material>
  <material name="green">
    <color rgba="0.0 0.8 0.0 1.0"/>
  </material>
  <material name="grey">
    <color rgba="0.2 0.2 0.2 1.0"/>
  </material>
  <material name="orange">
    <color rgba="1.0 0.423529411765 0.0392156862745 1.0"/>
  </material>
  <material name="brown">
    <color rgba="0.870588235294 0.811764705882 0.764705882353 1.0"/>
  </material>
  <material name="red">
    <color rgba="0.8 0.0 0.0 1.0"/>
  </material>
  <material name="white">
    <color rgba="1.0 1.0 1.0 1.0"/>
  </material>
  <!-- Used for fixing robot in the world -->
  <link name="world_link"/>
  <joint name="base_joint" type="fixed">
    <origin rpy="0 0 0" xyz="0 0 0"/>
    <parent link="world_link"/>
    <child link="base_link"/>
  </joint>
  <link name="base_link">
    <inertial>
      <mass value="5"/>
      <origin rpy="0 0 0" xyz="0 0 0.05"/>
      <inertia ixx="0.001" ixy="0.0" ixz="0.0" iyy="0.001" iyz="0.0" izz="0.001"/>
    </inertial>
    <visual>
      <origin rpy="0 0 0" xyz="0 0 0.05"/>
      <geometry>
        <cylinder length="0.10" radius="0.075"/>
      </geometry>
      <material name="trousers"/>
    </visual>
    <collision>
      <origin rpy="0 0 0" xyz="0 0 0.05"/>
      <geometry>
        <cylinder length="0.10" radius="0.075"/>
      </geometry>
    </collision>
  </link>
  <joint name="base_top_joint" type="fixed">
    <origin rpy="0 0 0" xyz="0 0 0.10"/>
    <parent link="base_link"/>
    <child link="base_top_link"/>
  </joint>
  <link name="base_top_link">
    <inertial>
      <origin rpy="0 0 0" xyz="0 0 0"/>
      <mass value="0.0001"/>
      <inertia ixx="0.001" ixy="0.0" ixz="0.0" iyy="0.001" iyz="0.0" izz="0.001"/>
    </inertial>
    <visual>
      <origin rpy="0 0 0" xyz="0 0 0"/>
      <geometry>
        <cylinder length="0.001" radius="0.01"/>
      </geometry>
      <material name="mount"/>
    </visual>
  </link>
  <gazebo reference="base_top_link">
    <material>Gazebo/Black</material>
  </gazebo>
  <joint name="base_leg_l_joint" type="fixed">
    <origin rpy="0 1.57079632679 0.785398163397" xyz="0.053033009 0.053033009 0.03"/>
    <parent link="base_link"/>
    <child link="base_leg_l_link"/>
  </joint>
  <link name="base_leg_l_link">
    <inertial>
      <origin rpy="0 0 0" xyz="0 0 0"/>
      <mass value="0.0001"/>
      <inertia ixx="0.001" ixy="0.0" ixz="0.0" iyy="0.001" iyz="0.0" izz="0.001"/>
    </inertial>
    <visual>
      <origin rpy="0 0 0" xyz="0 0 0"/>
      <geometry>
        <cylinder length="0.001" radius="0.01"/>
      </geometry>
      <material name="mount"/>
    </visual>
  </link>
  <gazebo reference="base_leg_l_link">
    <material>Gazebo/Black</material>
  </gazebo>
  <joint name="base_leg_r_joint" type="fixed">
    <origin rpy="0 1.57079632679 -0.785398163397" xyz="0.053033009 -0.053033009 0.03"/>
    <parent link="base_link"/>
    <child link="base_leg_r_link"/>
  </joint>
  <link name="base_leg_r_link">
    <inertial>
      <origin rpy="0 0 0" xyz="0 0 0"/>
      <mass value="0.0001"/>
      <inertia ixx="0.001" ixy="0.0" ixz="0.0" iyy="0.001" iyz="0.0" izz="0.001"/>
    </inertial>
    <visual>
      <origin rpy="0 0 0" xyz="0 0 0"/>
      <geometry>
        <cylinder length="0.001" radius="0.01"/>
      </geometry>
      <material name="mount"/>
    </visual>
  </link>
  <gazebo reference="base_leg_r_link">
    <material>Gazebo/Black</material>
  </gazebo>
  <gazebo reference="base_link">
    <material>Gazebo/Blue</material>
  </gazebo>
  <joint name="leg_l_mount_joint" type="fixed">
    <origin rpy="0 0 0" xyz="0 0 0"/>
    <parent link="base_leg_l_link"/>
    <child link="leg_l_mount_link"/>
  </joint>
  <link name="leg_l_mount_link">
    <inertial>
      <origin rpy="0 0 0" xyz="0 0 0"/>
      <mass value="0.0001"/>
      <inertia ixx="0.001" ixy="0.0" ixz="0.0" iyy="0.001" iyz="0.0" izz="0.001"/>
    </inertial>
    <visual>
      <origin rpy="0 0 0" xyz="0 0 0"/>
      <geometry>
        <cylinder length="0.001" radius="0.01"/>
      </geometry>
      <material name="mount"/>
    </visual>
  </link>
  <gazebo reference="leg_l_mount_link">
    <material>Gazebo/Black</material>
  </gazebo>
  <joint name="leg_l_joint" type="fixed">
    <origin rpy="0 0 0" xyz="0 0 0"/>
    <parent link="leg_l_mount_link"/>
    <child link="leg_l_link"/>
  </joint>
  <link name="leg_l_link">
    <inertial>
      <mass value="0.1"/>
      <inertia ixx="0.001" ixy="0.0" ixz="0.0" iyy="0.001" iyz="0.0" izz="0.001"/>
    </inertial>
    <visual>
      <origin rpy="0 0 0" xyz="0 0 0.05"/>
      <geometry>
        <cylinder length="0.10" radius="0.03"/>
      </geometry>
      <material name="trousers"/>
    </visual>
    <collision>
      <origin rpy="0 0 0" xyz="0 0 0.05"/>
      <geometry>
        <cylinder length="0.10" radius="0.03"/>
      </geometry>
    </collision>
  </link>
  <joint name="leg_l_foot_joint" type="fixed">
    <origin rpy="0 0 0" xyz="0 0 0.10"/>
    <parent link="leg_l_link"/>
    <child link="leg_l_foot_link"/>
  </joint>
  <link name="leg_l_foot_link">
    <inertial>
      <origin rpy="0 0 0" xyz="0 0 0"/>
      <mass value="0.0001"/>
      <inertia ixx="0.001" ixy="0.0" ixz="0.0" iyy="0.001" iyz="0.0" izz="0.001"/>
    </inertial>
    <visual>
      <origin rpy="0 0 0" xyz="0 0 0"/>
      <geometry>
        <cylinder length="0.001" radius="0.01"/>
      </geometry>
      <material name="mount"/>
    </visual>
  </link>
  <gazebo reference="leg_l_foot_link">
    <material>Gazebo/Black</material>
  </gazebo>
  <gazebo reference="leg_l_link">
    <material>Gazebo/Blue</material>
  </gazebo>
  <joint name="foot_l_mount_joint" type="fixed">
    <origin rpy="0 0 0" xyz="0 0 0"/>
    <parent link="leg_l_foot_link"/>
    <child link="foot_l_mount_link"/>
  </joint>
  <link name="foot_l_mount_link">
    <inertial>
      <origin rpy="0 0 0" xyz="0 0 0"/>
      <mass value="0.0001"/>
      <inertia ixx="0.001" ixy="0.0" ixz="0.0" iyy="0.001" iyz="0.0" izz="0.001"/>
    </inertial>
    <visual>
      <origin rpy="0 0 0" xyz="0 0 0"/>
      <geometry>
        <cylinder length="0.001" radius="0.01"/>
      </geometry>
      <material name="mount"/>
    </visual>
  </link>
  <gazebo reference="foot_l_mount_link">
    <material>Gazebo/Black</material>
  </gazebo>
  <joint name="foot_l_ankle_joint" type="fixed">
    <origin rpy="0 -1.57079 0" xyz="-0.0125 0 0.025"/>
    <parent link="foot_l_mount_link"/>
    <child link="foot_l_link"/>
  </joint>
  <link name="foot_l_link">
    <inertial>
      <mass value="0.01"/>
      <inertia ixx="0.001" ixy="0.0" ixz="0.0" iyy="0.001" iyz="0.0" izz="0.001"/>
    </inertial>
    <visual>
      <origin rpy="0 0 0" xyz="0 0 0"/>
      <geometry>
        <cylinder length="0.075" radius="0.025"/>
      </geometry>
      <material name="skin"/>
    </visual>
    <collision>
      <origin rpy="0 0 0" xyz="0 0 0"/>
      <geometry>
        <cylinder length="0.075" radius="0.025"/>
      </geometry>
    </collision>
  </link>
  <joint name="foot_l_toe_joint" type="fixed">
    <origin rpy="0 0 0" xyz="0 0 0.0375"/>
    <parent link="foot_l_link"/>
    <child link="foot_l_toe_link"/>
  </joint>
  <link name="foot_l_toe_link">
    <inertial>
      <origin rpy="0 0 0" xyz="0 0 0"/>
      <mass value="0.0001"/>
      <inertia ixx="0.001" ixy="0.0" ixz="0.0" iyy="0.001" iyz="0.0" izz="0.001"/>
    </inertial>
    <visual>
      <origin rpy="0 0 0" xyz="0 0 0"/>
      <geometry>
        <cylinder length="0.001" radius="0.01"/>
      </geometry>
      <material name="mount"/>
    </visual>
  </link>
  <gazebo reference="foot_l_toe_link">
    <material>Gazebo/Black</material>
  </gazebo>
  <gazebo reference="foot_l_link">
    <material>Gazebo/Yellow</material>
  </gazebo>
  <joint name="leg_r_mount_joint" type="fixed">
    <origin rpy="0 0 0" xyz="0 0 0"/>
    <parent link="base_leg_r_link"/>
    <child link="leg_r_mount_link"/>
  </joint>
  <link name="leg_r_mount_link">
    <inertial>
      <origin rpy="0 0 0" xyz="0 0 0"/>
      <mass value="0.0001"/>
      <inertia ixx="0.001" ixy="0.0" ixz="0.0" iyy="0.001" iyz="0.0" izz="0.001"/>
    </inertial>
    <visual>
      <origin rpy="0 0 0" xyz="0 0 0"/>
      <geometry>
        <cylinder length="0.001" radius="0.01"/>
      </geometry>
      <material name="mount"/>
    </visual>
  </link>
  <gazebo reference="leg_r_mount_link">
    <material>Gazebo/Black</material>
  </gazebo>
  <joint name="leg_r_joint" type="fixed">
    <origin rpy="0 0 0" xyz="0 0 0"/>
    <parent link="leg_r_mount_link"/>
    <child link="leg_r_link"/>
  </joint>
  <link name="leg_r_link">
    <inertial>
      <mass value="0.1"/>
      <inertia ixx="0.001" ixy="0.0" ixz="0.0" iyy="0.001" iyz="0.0" izz="0.001"/>
    </inertial>
    <visual>
      <origin rpy="0 0 0" xyz="0 0 0.05"/>
      <geometry>
        <cylinder length="0.10" radius="0.03"/>
      </geometry>
      <material name="trousers"/>
    </visual>
    <collision>
      <origin rpy="0 0 0" xyz="0 0 0.05"/>
      <geometry>
        <cylinder length="0.10" radius="0.03"/>
      </geometry>
    </collision>
  </link>
  <joint name="leg_r_foot_joint" type="fixed">
    <origin rpy="0 0 0" xyz="0 0 0.10"/>
    <parent link="leg_r_link"/>
    <child link="leg_r_foot_link"/>
  </joint>
  <link name="leg_r_foot_link">
    <inertial>
      <origin rpy="0 0 0" xyz="0 0 0"/>
      <mass value="0.0001"/>
      <inertia ixx="0.001" ixy="0.0" ixz="0.0" iyy="0.001" iyz="0.0" izz="0.001"/>
    </inertial>
    <visual>
      <origin rpy="0 0 0" xyz="0 0 0"/>
      <geometry>
        <cylinder length="0.001" radius="0.01"/>
      </geometry>
      <material name="mount"/>
    </visual>
  </link>
  <gazebo reference="leg_r_foot_link">
    <material>Gazebo/Black</material>
  </gazebo>
  <gazebo reference="leg_r_link">
    <material>Gazebo/Blue</material>
  </gazebo>
  <joint name="foot_r_mount_joint" type="fixed">
    <origin rpy="0 0 0" xyz="0 0 0"/>
    <parent link="leg_r_foot_link"/>
    <child link="foot_r_mount_link"/>
  </joint>
  <link name="foot_r_mount_link">
    <inertial>
      <origin rpy="0 0 0" xyz="0 0 0"/>
      <mass value="0.0001"/>
      <inertia ixx="0.001" ixy="0.0" ixz="0.0" iyy="0.001" iyz="0.0" izz="0.001"/>
    </inertial>
    <visual>
      <origin rpy="0 0 0" xyz="0 0 0"/>
      <geometry>
        <cylinder length="0.001" radius="0.01"/>
      </geometry>
      <material name="mount"/>
    </visual>
  </link>
  <gazebo reference="foot_r_mount_link">
    <material>Gazebo/Black</material>
  </gazebo>
  <joint name="foot_r_ankle_joint" type="fixed">
    <origin rpy="0 -1.57079 0" xyz="-0.0125 0 0.025"/>
    <parent link="foot_r_mount_link"/>
    <child link="foot_r_link"/>
  </joint>
  <link name="foot_r_link">
    <inertial>
      <mass value="0.01"/>
      <inertia ixx="0.001" ixy="0.0" ixz="0.0" iyy="0.001" iyz="0.0" izz="0.001"/>
    </inertial>
    <visual>
      <origin rpy="0 0 0" xyz="0 0 0"/>
      <geometry>
        <cylinder length="0.075" radius="0.025"/>
      </geometry>
      <material name="skin"/>
    </visual>
    <collision>
      <origin rpy="0 0 0" xyz="0 0 0"/>
      <geometry>
        <cylinder length="0.075" radius="0.025"/>
      </geometry>
    </collision>
  </link>
  <joint name="foot_r_toe_joint" type="fixed">
    <origin rpy="0 0 0" xyz="0 0 0.0375"/>
    <parent link="foot_r_link"/>
    <child link="foot_r_toe_link"/>
  </joint>
  <link name="foot_r_toe_link">
    <inertial>
      <origin rpy="0 0 0" xyz="0 0 0"/>
      <mass value="0.0001"/>
      <inertia ixx="0.001" ixy="0.0" ixz="0.0" iyy="0.001" iyz="0.0" izz="0.001"/>
    </inertial>
    <visual>
      <origin rpy="0 0 0" xyz="0 0 0"/>
      <geometry>
        <cylinder length="0.001" radius="0.01"/>
      </geometry>
      <material name="mount"/>
    </visual>
  </link>
  <gazebo reference="foot_r_toe_link">
    <material>Gazebo/Black</material>
  </gazebo>
  <gazebo reference="foot_r_link">
    <material>Gazebo/Yellow</material>
  </gazebo>
  <joint name="torso_mount_joint" type="fixed">
    <origin rpy="0 0 0" xyz="0 0 0"/>
    <parent link="base_top_link"/>
    <child link="torso_mount_link"/>
  </joint>
  <link name="torso_mount_link">
    <inertial>
      <origin rpy="0 0 0" xyz="0 0 0"/>
      <mass value="0.0001"/>
      <inertia ixx="0.001" ixy="0.0" ixz="0.0" iyy="0.001" iyz="0.0" izz="0.001"/>
    </inertial>
    <visual>
      <origin rpy="0 0 0" xyz="0 0 0"/>
      <geometry>
        <cylinder length="0.001" radius="0.01"/>
      </geometry>
      <material name="mount"/>
    </visual>
  </link>
  <gazebo reference="torso_mount_link">
    <material>Gazebo/Black</material>
  </gazebo>
  <joint name="torso_joint" type="revolute">
    <origin rpy="0 0 0" xyz="0 0 0"/>
    <parent link="torso_mount_link"/>
    <child link="torso_link"/>
    <axis xyz="0 0 1"/>
    <limit effort="0" lower="-1.5707" upper="1.5707" velocity="1"/>
  </joint>
  <link name="torso_link">
    <inertial>
      <mass value="5"/>
      <origin rpy="0 0 0" xyz="0 0 0.08"/>
      <inertia ixx="0.001" ixy="0.0" ixz="0.0" iyy="0.001" iyz="0.0" izz="0.001"/>
    </inertial>
    <visual>
      <origin rpy="0 0 0" xyz="0 0 0.08"/>
      <geometry>
        <cylinder length="0.15" radius="0.08"/>
      </geometry>
      <material name="shell"/>
    </visual>
    <collision>
      <origin rpy="0 0 0" xyz="0 0 0.08"/>
      <geometry>
        <cylinder length="0.15" radius="0.08"/>
      </geometry>
    </collision>
  </link>
  <joint name="torso_top_joint" type="fixed">
    <origin rpy="0 0 0" xyz="0 0 0.155"/>
    <parent link="torso_link"/>
    <child link="torso_top_link"/>
  </joint>
  <link name="torso_top_link">
    <inertial>
      <origin rpy="0 0 0" xyz="0 0 0"/>
      <mass value="0.0001"/>
      <inertia ixx="0.001" ixy="0.0" ixz="0.0" iyy="0.001" iyz="0.0" izz="0.001"/>
    </inertial>
    <visual>
      <origin rpy="0 0 0" xyz="0 0 0"/>
      <geometry>
        <cylinder length="0.001" radius="0.01"/>
      </geometry>
      <material name="mount"/>
    </visual>
  </link>
  <gazebo reference="torso_top_link">
    <material>Gazebo/Black</material>
  </gazebo>
  <joint name="torso_arm_l_joint" type="fixed">
    <origin rpy="-1.57079 0 0" xyz="0 0.08 0.12"/>
    <parent link="torso_link"/>
    <child link="torso_arm_l_link"/>
  </joint>
  <link name="torso_arm_l_link">
    <inertial>
      <origin rpy="0 0 0" xyz="0 0 0"/>
      <mass value="0.0001"/>
      <inertia ixx="0.001" ixy="0.0" ixz="0.0" iyy="0.001" iyz="0.0" izz="0.001"/>
    </inertial>
    <visual>
      <origin rpy="0 0 0" xyz="0 0 0"/>
      <geometry>
        <cylinder length="0.001" radius="0.01"/>
      </geometry>
      <material name="mount"/>
    </visual>
  </link>
  <gazebo reference="torso_arm_l_link">
    <material>Gazebo/Black</material>
  </gazebo>
  <joint name="torso_arm_r_joint" type="fixed">
    <origin rpy="1.57079 0 0" xyz="0 -0.08 0.12"/>
    <parent link="torso_link"/>
    <child link="torso_arm_r_link"/>
  </joint>
  <link name="torso_arm_r_link">
    <inertial>
      <origin rpy="0 0 0" xyz="0 0 0"/>
      <mass value="0.0001"/>
      <inertia ixx="0.001" ixy="0.0" ixz="0.0" iyy="0.001" iyz="0.0" izz="0.001"/>
    </inertial>
    <visual>
      <origin rpy="0 0 0" xyz="0 0 0"/>
      <geometry>
        <cylinder length="0.001" radius="0.01"/>
      </geometry>
      <material name="mount"/>
    </visual>
  </link>
  <gazebo reference="torso_arm_r_link">
    <material>Gazebo/Black</material>
  </gazebo>
  <gazebo reference="torso_link">
    <material>Gazebo/White</material>
  </gazebo>
  <joint name="arm_r_mount_joint" type="fixed">
    <origin rpy="0 0 0" xyz="0 0 0"/>
    <parent link="torso_arm_r_link"/>
    <child link="arm_r_mount_link"/>
  </joint>
  <link name="arm_r_mount_link">
    <inertial>
      <origin rpy="0 0 0" xyz="0 0 0"/>
      <mass value="0.0001"/>
      <inertia ixx="0.001" ixy="0.0" ixz="0.0" iyy="0.001" iyz="0.0" izz="0.001"/>
    </inertial>
    <visual>
      <origin rpy="0 0 0" xyz="0 0 0"/>
      <geometry>
        <cylinder length="0.001" radius="0.01"/>
      </geometry>
      <material name="mount"/>
    </visual>
  </link>
  <gazebo reference="arm_r_mount_link">
    <material>Gazebo/Black</material>
  </gazebo>
  <joint name="arm_r_0_mount_joint" type="fixed">
    <origin xyz="0 0 0"/>
    <parent link="arm_r_mount_link"/>
    <child link="arm_r_0_mount_link"/>
  </joint>
  <link name="arm_r_0_mount_link">
    <inertial>
      <origin rpy="0 0 0" xyz="0 0 0"/>
      <mass value="0.0001"/>
      <inertia ixx="0.001" ixy="0.0" ixz="0.0" iyy="0.001" iyz="0.0" izz="0.001"/>
    </inertial>
    <visual>
      <origin rpy="0 0 0" xyz="0 0 0"/>
      <geometry>
        <cylinder length="0.001" radius="0.01"/>
      </geometry>
      <material name="mount"/>
    </visual>
  </link>
  <gazebo reference="arm_r_0_mount_link">
    <material>Gazebo/Black</material>
  </gazebo>
  <link name="arm_r_0_box_link">
    <visual>
      <geometry name="x01">
        <box size="0.050 0.038 0.032"/>
      </geometry>
      <material name="plastic_black"/>
    </visual>
    <inertial>
      <mass value="0.01"/>
      <inertia ixx="0.001" ixy="0.0" ixz="0.0" iyy="0.001" iyz="0.0" izz="0.001"/>
    </inertial>
    <collision>
      <geometry name="x01">
        <box size="0.050 0.038 0.032"/>
      </geometry>
    </collision>
  </link>
  <joint name="arm_r_0_box_bottom_joint" type="fixed">
    <origin rpy="0 1.57079 0" xyz="0.025 0 0"/>
    <parent link="arm_r_0_box_link"/>
    <child link="arm_r_0_box_bottom_link"/>
  </joint>
  <link name="arm_r_0_box_bottom_link">
    <inertial>
      <origin rpy="0 0 0" xyz="0 0 0"/>
      <mass value="0.0001"/>
      <inertia ixx="0.001" ixy="0.0" ixz="0.0" iyy="0.001" iyz="0.0" izz="0.001"/>
    </inertial>
    <visual>
      <origin rpy="0 0 0" xyz="0 0 0"/>
      <geometry>
        <cylinder length="0.001" radius="0.01"/>
      </geometry>
      <material name="mount"/>
    </visual>
  </link>
  <gazebo reference="arm_r_0_box_bottom_link">
    <material>Gazebo/Black</material>
  </gazebo>
  <joint name="arm_r_0_box_top_joint" type="fixed">
    <origin rpy="0 -1.57079 0" xyz="-0.025 0 0"/>
    <parent link="arm_r_0_box_link"/>
    <child link="arm_r_0_box_top_link"/>
  </joint>
  <link name="arm_r_0_box_top_link">
    <inertial>
      <origin rpy="0 0 0" xyz="0 0 0"/>
      <mass value="0.0001"/>
      <inertia ixx="0.001" ixy="0.0" ixz="0.0" iyy="0.001" iyz="0.0" izz="0.001"/>
    </inertial>
    <visual>
      <origin rpy="0 0 0" xyz="0 0 0"/>
      <geometry>
        <cylinder length="0.001" radius="0.01"/>
      </geometry>
      <material name="mount"/>
    </visual>
  </link>
  <gazebo reference="arm_r_0_box_top_link">
    <material>Gazebo/Black</material>
  </gazebo>
  <joint name="arm_r_0_box_axel_joint" type="fixed">
    <origin rpy="1.57075 0 3.14159" xyz="-0.012 0.019 0"/>
    <parent link="arm_r_0_box_link"/>
    <child link="arm_r_0_box_axel_link"/>
  </joint>
  <link name="arm_r_0_box_axel_link">
    <inertial>
      <origin rpy="0 0 0" xyz="0 0 0"/>
      <mass value="0.0001"/>
      <inertia ixx="0.001" ixy="0.0" ixz="0.0" iyy="0.001" iyz="0.0" izz="0.001"/>
    </inertial>
    <visual>
      <origin rpy="0 0 0" xyz="0 0 0"/>
      <geometry>
        <cylinder length="0.001" radius="0.01"/>
      </geometry>
      <material name="mount"/>
    </visual>
  </link>
  <gazebo reference="arm_r_0_box_axel_link">
    <material>Gazebo/Black</material>
  </gazebo>
  <joint name="arm_r_0_box_joint" type="fixed">
    <origin rpy="1.57079 0 -1.57079" xyz="0 0 0.019"/>
    <parent link="arm_r_0_mount_link"/>
    <child link="arm_r_0_box_link"/>
  </joint>
  <link name="arm_r_0_axel_box_link">
    <visual>
      <geometry>
        <cylinder length="0.005" radius="0.011"/>
      </geometry>
      <material name="plastic_white"/>
    </visual>
    <inertial>
      <mass value="0.001"/>
      <inertia ixx="0.001" ixy="0.0" ixz="0.0" iyy="0.001" iyz="0.0" izz="0.001"/>
    </inertial>
    <collision>
      <geometry>
        <cylinder length="0.005" radius="0.011"/>
      </geometry>
    </collision>
  </link>
  <joint name="arm_r_0_axel_joint" type="fixed">
    <origin rpy="0 0 1.57079" xyz="0 0 0.0025"/>
    <parent link="arm_r_0_axel_box_link"/>
    <child link="arm_r_0_axel_link"/>
  </joint>
  <link name="arm_r_0_axel_link">
    <inertial>
      <origin rpy="0 0 0" xyz="0 0 0"/>
      <mass value="0.0001"/>
      <inertia ixx="0.001" ixy="0.0" ixz="0.0" iyy="0.001" iyz="0.0" izz="0.001"/>
    </inertial>
    <visual>
      <origin rpy="0 0 0" xyz="0 0 0"/>
      <geometry>
        <cylinder length="0.001" radius="0.01"/>
      </geometry>
      <material name="mount"/>
    </visual>
  </link>
  <gazebo reference="arm_r_0_axel_link">
    <material>Gazebo/Black</material>
  </gazebo>
  <joint name="arm_r_0_axel_box_joint" type="revolute">
    <parent link="arm_r_0_box_axel_link"/>
    <child link="arm_r_0_axel_box_link"/>
    <origin rpy="0 0 0" xyz="0 0 0"/>
    <axis xyz="1 0 0"/>
    <limit effort="0" lower="-1.5707" upper="1.5707" velocity="1"/>
  </joint>
  <transmission name="arm_r_0_trans">
    <type>transmission_interface/SimpleTransmission</type>
    <joint name="arm_r_0_joint">
      <hardwareInterface>PositionJointInterface</hardwareInterface>
    </joint>
    <actuator name="arm_r_0_motor">
      <hardwareInterface>PositionJointInterface</hardwareInterface>
      <mechanicalReduction>1</mechanicalReduction>
    </actuator>
  </transmission>
  <gazebo reference="arm_r_0_box_link">
    <material>Gazebo/White</material>
  </gazebo>
  <gazebo reference="arm_r_0_box_axel_link">
    <material>Gazebo/White</material>
  </gazebo>
  <joint name="arm_r_1_mount_joint" type="fixed">
    <origin xyz="0 0 0"/>
    <parent link="arm_r_0_axel_link"/>
    <child link="arm_r_1_mount_link"/>
  </joint>
  <link name="arm_r_1_mount_link">
    <inertial>
      <origin rpy="0 0 0" xyz="0 0 0"/>
      <mass value="0.0001"/>
      <inertia ixx="0.001" ixy="0.0" ixz="0.0" iyy="0.001" iyz="0.0" izz="0.001"/>
    </inertial>
    <visual>
      <origin rpy="0 0 0" xyz="0 0 0"/>
      <geometry>
        <cylinder length="0.001" radius="0.01"/>
      </geometry>
      <material name="mount"/>
    </visual>
  </link>
  <gazebo reference="arm_r_1_mount_link">
    <material>Gazebo/Black</material>
  </gazebo>
  <link name="arm_r_1_box_link">
    <visual>
      <geometry name="x01">
        <box size="0.050 0.038 0.032"/>
      </geometry>
      <material name="plastic_black"/>
    </visual>
    <inertial>
      <mass value="0.01"/>
      <inertia ixx="0.001" ixy="0.0" ixz="0.0" iyy="0.001" iyz="0.0" izz="0.001"/>
    </inertial>
    <collision>
      <geometry name="x01">
        <box size="0.050 0.038 0.032"/>
      </geometry>
    </collision>
  </link>
  <joint name="arm_r_1_box_back_joint" type="fixed">
    <origin rpy="1.57079 0 0" xyz="0 0.019 0"/>
    <parent link="arm_r_1_box_link"/>
    <child link="arm_r_1_box_back_link"/>
  </joint>
  <link name="arm_r_1_box_back_link">
    <inertial>
      <origin rpy="0 0 0" xyz="0 0 0"/>
      <mass value="0.0001"/>
      <inertia ixx="0.001" ixy="0.0" ixz="0.0" iyy="0.001" iyz="0.0" izz="0.001"/>
    </inertial>
    <visual>
      <origin rpy="0 0 0" xyz="0 0 0"/>
      <geometry>
        <cylinder length="0.001" radius="0.01"/>
      </geometry>
      <material name="mount"/>
    </visual>
  </link>
  <gazebo reference="arm_r_1_box_back_link">
    <material>Gazebo/Black</material>
  </gazebo>
  <joint name="arm_r_1_box_top_joint" type="fixed">
    <origin rpy="0 -1.57079 0" xyz="-0.025 0 0"/>
    <parent link="arm_r_1_box_link"/>
    <child link="arm_r_1_box_top_link"/>
  </joint>
  <link name="arm_r_1_box_top_link">
    <inertial>
      <origin rpy="0 0 0" xyz="0 0 0"/>
      <mass value="0.0001"/>
      <inertia ixx="0.001" ixy="0.0" ixz="0.0" iyy="0.001" iyz="0.0" izz="0.001"/>
    </inertial>
    <visual>
      <origin rpy="0 0 0" xyz="0 0 0"/>
      <geometry>
        <cylinder length="0.001" radius="0.01"/>
      </geometry>
      <material name="mount"/>
    </visual>
  </link>
  <gazebo reference="arm_r_1_box_top_link">
    <material>Gazebo/Black</material>
  </gazebo>
  <joint name="arm_r_1_box_axel_joint" type="fixed">
    <origin rpy="1.57075 0 3.14159" xyz="-0.012 0.019 0"/>
    <parent link="arm_r_1_box_link"/>
    <child link="arm_r_1_box_axel_link"/>
  </joint>
  <link name="arm_r_1_box_axel_link">
    <inertial>
      <origin rpy="0 0 0" xyz="0 0 0"/>
      <mass value="0.0001"/>
      <inertia ixx="0.001" ixy="0.0" ixz="0.0" iyy="0.001" iyz="0.0" izz="0.001"/>
    </inertial>
    <visual>
      <origin rpy="0 0 0" xyz="0 0 0"/>
      <geometry>
        <cylinder length="0.001" radius="0.01"/>
      </geometry>
      <material name="mount"/>
    </visual>
  </link>
  <gazebo reference="arm_r_1_box_axel_link">
    <material>Gazebo/Black</material>
  </gazebo>
  <joint name="arm_r_1_box_joint" type="fixed">
    <origin rpy="0 1.57079 0" xyz="0.025 0 0"/>
    <parent link="arm_r_1_mount_link"/>
    <child link="arm_r_1_box_link"/>
  </joint>
  <link name="arm_r_1_axel_box_link">
    <visual>
      <geometry>
        <cylinder length="0.005" radius="0.011"/>
      </geometry>
      <material name="plastic_white"/>
    </visual>
    <inertial>
      <mass value="0.001"/>
      <inertia ixx="0.001" ixy="0.0" ixz="0.0" iyy="0.001" iyz="0.0" izz="0.001"/>
    </inertial>
    <collision>
      <geometry>
        <cylinder length="0.005" radius="0.011"/>
      </geometry>
    </collision>
  </link>
  <joint name="arm_r_1_axel_joint" type="fixed">
    <origin rpy="0 0 1.57079" xyz="0 0 0.0025"/>
    <parent link="arm_r_1_axel_box_link"/>
    <child link="arm_r_1_axel_link"/>
  </joint>
  <link name="arm_r_1_axel_link">
    <inertial>
      <origin rpy="0 0 0" xyz="0 0 0"/>
      <mass value="0.0001"/>
      <inertia ixx="0.001" ixy="0.0" ixz="0.0" iyy="0.001" iyz="0.0" izz="0.001"/>
    </inertial>
    <visual>
      <origin rpy="0 0 0" xyz="0 0 0"/>
      <geometry>
        <cylinder length="0.001" radius="0.01"/>
      </geometry>
      <material name="mount"/>
    </visual>
  </link>
  <gazebo reference="arm_r_1_axel_link">
    <material>Gazebo/Black</material>
  </gazebo>
  <joint name="arm_r_1_axel_box_joint" type="revolute">
    <parent link="arm_r_1_box_axel_link"/>
    <child link="arm_r_1_axel_box_link"/>
    <origin rpy="0 0 0" xyz="0 0 0"/>
    <axis xyz="1 0 0"/>
    <limit effort="0" lower="-1.5707" upper="1.5707" velocity="1"/>
  </joint>
  <transmission name="arm_r_1_trans">
    <type>transmission_interface/SimpleTransmission</type>
    <joint name="arm_r_1_joint">
      <hardwareInterface>PositionJointInterface</hardwareInterface>
    </joint>
    <actuator name="arm_r_1_motor">
      <hardwareInterface>PositionJointInterface</hardwareInterface>
      <mechanicalReduction>1</mechanicalReduction>
    </actuator>
  </transmission>
  <gazebo reference="arm_r_1_box_link">
    <material>Gazebo/White</material>
  </gazebo>
  <gazebo reference="arm_r_1_box_axel_link">
    <material>Gazebo/White</material>
  </gazebo>
  <joint name="arm_r_2_mount_joint" type="fixed">
    <origin xyz="0 0 0"/>
    <parent link="arm_r_1_axel_link"/>
    <child link="arm_r_2_mount_link"/>
  </joint>
  <link name="arm_r_2_mount_link">
    <inertial>
      <origin rpy="0 0 0" xyz="0 0 0"/>
      <mass value="0.0001"/>
      <inertia ixx="0.001" ixy="0.0" ixz="0.0" iyy="0.001" iyz="0.0" izz="0.001"/>
    </inertial>
    <visual>
      <origin rpy="0 0 0" xyz="0 0 0"/>
      <geometry>
        <cylinder length="0.001" radius="0.01"/>
      </geometry>
      <material name="mount"/>
    </visual>
  </link>
  <gazebo reference="arm_r_2_mount_link">
    <material>Gazebo/Black</material>
  </gazebo>
  <link name="arm_r_2_box_link">
    <visual>
      <geometry name="x01">
        <box size="0.050 0.038 0.032"/>
      </geometry>
      <material name="plastic_black"/>
    </visual>
    <inertial>
      <mass value="0.01"/>
      <inertia ixx="0.001" ixy="0.0" ixz="0.0" iyy="0.001" iyz="0.0" izz="0.001"/>
    </inertial>
    <collision>
      <geometry name="x01">
        <box size="0.050 0.038 0.032"/>
      </geometry>
    </collision>
  </link>
  <joint name="arm_r_2_box_back_joint" type="fixed">
    <origin rpy="1.57079 0 0" xyz="0 0.019 0"/>
    <parent link="arm_r_2_box_link"/>
    <child link="arm_r_2_box_back_link"/>
  </joint>
  <link name="arm_r_2_box_back_link">
    <inertial>
      <origin rpy="0 0 0" xyz="0 0 0"/>
      <mass value="0.0001"/>
      <inertia ixx="0.001" ixy="0.0" ixz="0.0" iyy="0.001" iyz="0.0" izz="0.001"/>
    </inertial>
    <visual>
      <origin rpy="0 0 0" xyz="0 0 0"/>
      <geometry>
        <cylinder length="0.001" radius="0.01"/>
      </geometry>
      <material name="mount"/>
    </visual>
  </link>
  <gazebo reference="arm_r_2_box_back_link">
    <material>Gazebo/Black</material>
  </gazebo>
  <joint name="arm_r_2_box_top_joint" type="fixed">
    <origin rpy="0 -1.57079 0" xyz="-0.025 0 0"/>
    <parent link="arm_r_2_box_link"/>
    <child link="arm_r_2_box_top_link"/>
  </joint>
  <link name="arm_r_2_box_top_link">
    <inertial>
      <origin rpy="0 0 0" xyz="0 0 0"/>
      <mass value="0.0001"/>
      <inertia ixx="0.001" ixy="0.0" ixz="0.0" iyy="0.001" iyz="0.0" izz="0.001"/>
    </inertial>
    <visual>
      <origin rpy="0 0 0" xyz="0 0 0"/>
      <geometry>
        <cylinder length="0.001" radius="0.01"/>
      </geometry>
      <material name="mount"/>
    </visual>
  </link>
  <gazebo reference="arm_r_2_box_top_link">
    <material>Gazebo/Black</material>
  </gazebo>
  <joint name="arm_r_2_box_axel_joint" type="fixed">
    <origin rpy="1.57075 0 3.14159" xyz="-0.012 0.019 0"/>
    <parent link="arm_r_2_box_link"/>
    <child link="arm_r_2_box_axel_link"/>
  </joint>
  <link name="arm_r_2_box_axel_link">
    <inertial>
      <origin rpy="0 0 0" xyz="0 0 0"/>
      <mass value="0.0001"/>
      <inertia ixx="0.001" ixy="0.0" ixz="0.0" iyy="0.001" iyz="0.0" izz="0.001"/>
    </inertial>
    <visual>
      <origin rpy="0 0 0" xyz="0 0 0"/>
      <geometry>
        <cylinder length="0.001" radius="0.01"/>
      </geometry>
      <material name="mount"/>
    </visual>
  </link>
  <gazebo reference="arm_r_2_box_axel_link">
    <material>Gazebo/Black</material>
  </gazebo>
  <joint name="arm_r_2_box_joint" type="fixed">
    <origin rpy="0 1.57079 0" xyz="0.025 0 0"/>
    <parent link="arm_r_2_mount_link"/>
    <child link="arm_r_2_box_link"/>
  </joint>
  <link name="arm_r_2_axel_box_link">
    <visual>
      <geometry>
        <cylinder length="0.005" radius="0.011"/>
      </geometry>
      <material name="plastic_white"/>
    </visual>
    <inertial>
      <mass value="0.001"/>
      <inertia ixx="0.001" ixy="0.0" ixz="0.0" iyy="0.001" iyz="0.0" izz="0.001"/>
    </inertial>
    <collision>
      <geometry>
        <cylinder length="0.005" radius="0.011"/>
      </geometry>
    </collision>
  </link>
  <joint name="arm_r_2_axel_joint" type="fixed">
    <origin rpy="0 0 1.57079" xyz="0 0 0.0025"/>
    <parent link="arm_r_2_axel_box_link"/>
    <child link="arm_r_2_axel_link"/>
  </joint>
  <link name="arm_r_2_axel_link">
    <inertial>
      <origin rpy="0 0 0" xyz="0 0 0"/>
      <mass value="0.0001"/>
      <inertia ixx="0.001" ixy="0.0" ixz="0.0" iyy="0.001" iyz="0.0" izz="0.001"/>
    </inertial>
    <visual>
      <origin rpy="0 0 0" xyz="0 0 0"/>
      <geometry>
        <cylinder length="0.001" radius="0.01"/>
      </geometry>
      <material name="mount"/>
    </visual>
  </link>
  <gazebo reference="arm_r_2_axel_link">
    <material>Gazebo/Black</material>
  </gazebo>
  <joint name="arm_r_2_axel_box_joint" type="revolute">
    <parent link="arm_r_2_box_axel_link"/>
    <child link="arm_r_2_axel_box_link"/>
    <origin rpy="0 0 0" xyz="0 0 0"/>
    <axis xyz="1 0 0"/>
    <limit effort="0" lower="-1.5707" upper="1.5707" velocity="1"/>
  </joint>
  <transmission name="arm_r_2_trans">
    <type>transmission_interface/SimpleTransmission</type>
    <joint name="arm_r_2_joint">
      <hardwareInterface>PositionJointInterface</hardwareInterface>
    </joint>
    <actuator name="arm_r_2_motor">
      <hardwareInterface>PositionJointInterface</hardwareInterface>
      <mechanicalReduction>1</mechanicalReduction>
    </actuator>
  </transmission>
  <gazebo reference="arm_r_2_box_link">
    <material>Gazebo/White</material>
  </gazebo>
  <gazebo reference="arm_r_2_box_axel_link">
    <material>Gazebo/White</material>
  </gazebo>
  <joint name="arm_r_3_mount_joint" type="fixed">
    <origin xyz="0 0 0"/>
    <parent link="arm_r_2_axel_link"/>
    <child link="arm_r_3_mount_link"/>
  </joint>
  <link name="arm_r_3_mount_link">
    <inertial>
      <origin rpy="0 0 0" xyz="0 0 0"/>
      <mass value="0.0001"/>
      <inertia ixx="0.001" ixy="0.0" ixz="0.0" iyy="0.001" iyz="0.0" izz="0.001"/>
    </inertial>
    <visual>
      <origin rpy="0 0 0" xyz="0 0 0"/>
      <geometry>
        <cylinder length="0.001" radius="0.01"/>
      </geometry>
      <material name="mount"/>
    </visual>
  </link>
  <gazebo reference="arm_r_3_mount_link">
    <material>Gazebo/Black</material>
  </gazebo>
  <link name="arm_r_3_box_link">
    <visual>
      <geometry name="x01">
        <box size="0.050 0.038 0.032"/>
      </geometry>
      <material name="plastic_black"/>
    </visual>
    <inertial>
      <mass value="0.01"/>
      <inertia ixx="0.001" ixy="0.0" ixz="0.0" iyy="0.001" iyz="0.0" izz="0.001"/>
    </inertial>
    <collision>
      <geometry name="x01">
        <box size="0.050 0.038 0.032"/>
      </geometry>
    </collision>
  </link>
  <joint name="arm_r_3_box_back_joint" type="fixed">
    <origin rpy="1.57079 0 0" xyz="0 0.019 0"/>
    <parent link="arm_r_3_box_link"/>
    <child link="arm_r_3_box_back_link"/>
  </joint>
  <link name="arm_r_3_box_back_link">
    <inertial>
      <origin rpy="0 0 0" xyz="0 0 0"/>
      <mass value="0.0001"/>
      <inertia ixx="0.001" ixy="0.0" ixz="0.0" iyy="0.001" iyz="0.0" izz="0.001"/>
    </inertial>
    <visual>
      <origin rpy="0 0 0" xyz="0 0 0"/>
      <geometry>
        <cylinder length="0.001" radius="0.01"/>
      </geometry>
      <material name="mount"/>
    </visual>
  </link>
  <gazebo reference="arm_r_3_box_back_link">
    <material>Gazebo/Black</material>
  </gazebo>
  <joint name="arm_r_3_box_top_joint" type="fixed">
    <origin rpy="0 -1.57079 0" xyz="-0.025 0 0"/>
    <parent link="arm_r_3_box_link"/>
    <child link="arm_r_3_box_top_link"/>
  </joint>
  <link name="arm_r_3_box_top_link">
    <inertial>
      <origin rpy="0 0 0" xyz="0 0 0"/>
      <mass value="0.0001"/>
      <inertia ixx="0.001" ixy="0.0" ixz="0.0" iyy="0.001" iyz="0.0" izz="0.001"/>
    </inertial>
    <visual>
      <origin rpy="0 0 0" xyz="0 0 0"/>
      <geometry>
        <cylinder length="0.001" radius="0.01"/>
      </geometry>
      <material name="mount"/>
    </visual>
  </link>
  <gazebo reference="arm_r_3_box_top_link">
    <material>Gazebo/Black</material>
  </gazebo>
  <joint name="arm_r_3_box_axel_joint" type="fixed">
    <origin rpy="1.57075 0 3.14159" xyz="-0.012 0.019 0"/>
    <parent link="arm_r_3_box_link"/>
    <child link="arm_r_3_box_axel_link"/>
  </joint>
  <link name="arm_r_3_box_axel_link">
    <inertial>
      <origin rpy="0 0 0" xyz="0 0 0"/>
      <mass value="0.0001"/>
      <inertia ixx="0.001" ixy="0.0" ixz="0.0" iyy="0.001" iyz="0.0" izz="0.001"/>
    </inertial>
    <visual>
      <origin rpy="0 0 0" xyz="0 0 0"/>
      <geometry>
        <cylinder length="0.001" radius="0.01"/>
      </geometry>
      <material name="mount"/>
    </visual>
  </link>
  <gazebo reference="arm_r_3_box_axel_link">
    <material>Gazebo/Black</material>
  </gazebo>
  <joint name="arm_r_3_box_joint" type="fixed">
    <origin rpy="0 1.57079 0" xyz="0.025 0 0"/>
    <parent link="arm_r_3_mount_link"/>
    <child link="arm_r_3_box_link"/>
  </joint>
  <link name="arm_r_3_axel_box_link">
    <visual>
      <geometry>
        <cylinder length="0.005" radius="0.011"/>
      </geometry>
      <material name="plastic_white"/>
    </visual>
    <inertial>
      <mass value="0.001"/>
      <inertia ixx="0.001" ixy="0.0" ixz="0.0" iyy="0.001" iyz="0.0" izz="0.001"/>
    </inertial>
    <collision>
      <geometry>
        <cylinder length="0.005" radius="0.011"/>
      </geometry>
    </collision>
  </link>
  <joint name="arm_r_3_axel_joint" type="fixed">
    <origin rpy="0 0 1.57079" xyz="0 0 0.0025"/>
    <parent link="arm_r_3_axel_box_link"/>
    <child link="arm_r_3_axel_link"/>
  </joint>
  <link name="arm_r_3_axel_link">
    <inertial>
      <origin rpy="0 0 0" xyz="0 0 0"/>
      <mass value="0.0001"/>
      <inertia ixx="0.001" ixy="0.0" ixz="0.0" iyy="0.001" iyz="0.0" izz="0.001"/>
    </inertial>
    <visual>
      <origin rpy="0 0 0" xyz="0 0 0"/>
      <geometry>
        <cylinder length="0.001" radius="0.01"/>
      </geometry>
      <material name="mount"/>
    </visual>
  </link>
  <gazebo reference="arm_r_3_axel_link">
    <material>Gazebo/Black</material>
  </gazebo>
  <joint name="arm_r_3_axel_box_joint" type="revolute">
    <parent link="arm_r_3_box_axel_link"/>
    <child link="arm_r_3_axel_box_link"/>
    <origin rpy="0 0 0" xyz="0 0 0"/>
    <axis xyz="1 0 0"/>
    <limit effort="0" lower="-1.5707" upper="1.5707" velocity="1"/>
  </joint>
  <transmission name="arm_r_3_trans">
    <type>transmission_interface/SimpleTransmission</type>
    <joint name="arm_r_3_joint">
      <hardwareInterface>PositionJointInterface</hardwareInterface>
    </joint>
    <actuator name="arm_r_3_motor">
      <hardwareInterface>PositionJointInterface</hardwareInterface>
      <mechanicalReduction>1</mechanicalReduction>
    </actuator>
  </transmission>
  <gazebo reference="arm_r_3_box_link">
    <material>Gazebo/White</material>
  </gazebo>
  <gazebo reference="arm_r_3_box_axel_link">
    <material>Gazebo/White</material>
  </gazebo>
  <joint name="arm_r_hand_joint" type="fixed">
    <origin rpy="0 0 0" xyz="0 0 0.10"/>
    <parent link="arm_r_3_box_link"/>
    <child link="arm_r_hand_link"/>
  </joint>
  <link name="arm_r_hand_link">
    <inertial>
      <origin rpy="0 0 0" xyz="0 0 0"/>
      <mass value="0.0001"/>
      <inertia ixx="0.001" ixy="0.0" ixz="0.0" iyy="0.001" iyz="0.0" izz="0.001"/>
    </inertial>
    <visual>
      <origin rpy="0 0 0" xyz="0 0 0"/>
      <geometry>
        <cylinder length="0.001" radius="0.01"/>
      </geometry>
      <material name="mount"/>
    </visual>
  </link>
  <gazebo reference="arm_r_hand_link">
    <material>Gazebo/Black</material>
  </gazebo>
  <!-- 
	<xacro:hand_v0 name="hand_r" parent="torso_arm_r_hand">
		<origin rpy="0 0 0" xyz="0 0 0" />
	</xacro:hand_v0>
	<xacro:arm_v0 name="arm_l" parent="torso_arm_l">
		<origin rpy="0 0 0" xyz="0 0 0" />
	</xacro:arm_v0>
	<xacro:hand_v0 name="hand_l" parent="torso_arm_l_hand">
		<origin rpy="0 0 0" xyz="0 0 0" />
	</xacro:hand_v0>

	<xacro:neck_v0 name="neck" parent="torso_top">
		<origin rpy="0 0 0" xyz="0 0 0" />
	</xacro:neck_v0>
	<xacro:head_v0 name="head" parent="neck_top">
		<origin rpy="0 0 0" xyz="0 0 0" />
	</xacro:head_v0> -->
</robot>
